Workbook
Name Roles: #REF!
Name Roles: #REF!

Sheet Filename
A1: RBR file name content | AM1: Only EE and LT file name content
A2: Project name | F2: _ | G2: Originator/ Supplier/ Contractor | H2: _ | I2: Volume_System/Zone | L2: _ | M2: Location | N2: _ | O2: Document type RBDTD-EE-DS3-DPS1_PLU_OP-058-ZZ_ZZZZ_IF_IS_VE_000001 | T2: _ | U2: Discipline code | AB2: _ | AC2: Project stage | AH2: _ | AI2: Number | AJ2: _ | AK2: Revision No. | AL2: _ | AM2: Drawing name | AN2: _ | AO2: Number of the buildings in the project | AP2: - | AQ2: Document's running number within the project
A3: EE file name relevant | C3: EE file name relevant | E3: EE file name relevant | O3: EE file name relevant | U3: EE file name relevant | AC3: EE file name relevant | AK3: EE file name relevant | AM3: EE file name relevant | AO3: LT file name relevant | AQ3: EE file name relevant
A4: LT file name relevant | C4: LT file name relevant | E4: LT file name relevant | O4: LT file name relevant | U4: LT file name relevant | AC4: LT file name relevant | AQ4: LT file name relevant
A5: PROJECT ID | B5: - | C5: SECTION ID | D5: - | E5: SUB-SECTION ID | G5: Abbreviation of the originator of the document Predefined list ORIGINATOR_SUPPLIER Provided by RB Rail AS | I5: VOLUME/SYSTEM | J5: - | K5: ZONE | M5: Code of the location. Predefined list LOCATION Provided by RB Rail AS | O5: Abbreviation of the document type. Predefined list DOCUMENT TYPE Provided by RB Rail AS | Q5: RBR document type | S5: EE document type | U5: RBR discipline | W5: RBR CODE | Y5: LOCAL CODE EHR | AA5: LOCAL CODE MNT | AC5: Stage Description | AE5: Stage Code RBR | AG5: Stage Code EE | AH5: _ | AI5: Unique ID number of each construction object 000001-999999 | AJ5: _ | AK5: Revision number 1-999 | AM5: Drawing name. No limitations. | AO5: Number of the buildings in the project. According to LST 1516:2015 | AQ5: Document's running number within the project According to LST 1516:2015 | AS5: LT RELEVANT | AZ5: EE and LT relevant
A6: Project name according to DTD TS Predefined list PROJECT ID Provided by RB Rail AS | C6: Section name according to DTD TS Predefined list SECTION ID Provided by RB Rail AS | E6: Sub-section name according to DTD TS Predefined list SUB-SECTION ID Provided by RB Rail AS | I6: Code of the volume/ system. Predefined list VOLUME_SYSTEM Provided by RB Rail AS | K6: Code of the zone. Predefined list ZONE Provided by RB Rail AS | Q6: RBR document type code Predefined list Provided by RB Rail AS | S6: EE document type code Predefined list Provided by RB Rail AS | U6: RBR discipline Predefined list Provided by RB Rail AS | W6: RBR discipline code Predefined list Provided by RB Rail AS | Y6: Discipline code according to local legislation Predefined list | AA6: Discipline code according to local legislation Predefined list | AC6: Abbreviation of the project stage. Predefined list PROJECT STAGE Provided by RB Rail AS | AE6: Abbreviation of the project stage. Predefined list PROJECT STAGE Provided by RB Rail AS | AG6: Abbreviation of the project stage. Predefined list PROJECT STAGE Provided by RB Rail AS | BA6: EE formatted
AY7: LT formatted | BA7: LT formatted
AS8: LT Project ID | AU8: LT Document type | AW8: LT Project Stage Code | AY8: Number of the building in the project | AZ8: Document's running number within the project | BC8: Preview of the EE EHR file name | BD8: Length of filename, charecters | BF8: Preview of the EE MNT file name | BG8: Length of filename, charecters | BI8: RBR file number | BJ8: Length of filename, charecters | BL8: RBR file number, with revision number (Only for IDOM) | BM8: Length of filename, charecters
A9: RBDTD-EE | B9: =IF(C9=0,"","-") -> - | C9: DS1 | D9: =IF(E9=0,"","-") -> - | E9: DPS1 | F9: =IF(G9=0,"","_") -> _ | G9: VER | H9: =IF(I9=0,"","_") -> _ | I9: CU102002 | J9: =IF(K9=0,"","-") -> - | K9: ZZ | L9: =IF(M9=0,"","_") -> _ | M9: ZZZZ | N9: =IF(O9=0,"","_") -> _ | O9: Survey | P9: =IF(Q9="","","-") -> - | Q9: =IF(O9="","",VLOOKUP(O9,'DOCUMENT TYPE'!$A$2:$D$805,2,)) -> SU | R9: =IF(S9="","","-") -> - | S9: =IF(O9="","",VLOOKUP(O9,'DOCUMENT TYPE'!$A$2:$D$805,3,)) -> 1 | T9: =IF(U9=0,"","_") -> _ | U9: Land Melioration | V9: =IF(W9="","","-") -> - | W9: =IF(U9="","",VLOOKUP(U9,'ACTIVITY & DISCIPLINE CODE'!$F$3:$I$1863,2,)) -> DR | X9: =IF(Y9="","","-") -> - | Y9: =IF(U9="","",VLOOKUP(U9,'ACTIVITY & DISCIPLINE CODE'!$F$3:$I$1863,3,)) -> VK | Z9: =IF(AA9="","","_") -> _ | AA9: =IF(U9="","",VLOOKUP(U9,'ACTIVITY & DISCIPLINE CODE'!$F$3:$I$1863,4,)) -> DR | AB9: =IF(AC9=0,"","_") -> _ | AC9: Detailed Technical Design | AD9: =IF(AE9="","","-") -> - | AE9: =IF(AC9="","",VLOOKUP(AC9,'PROJECT STAGE'!$A$2:$C$100,2,)) -> DTD | AF9: =IF(AG9="","","_") -> _ | AG9: =IF(AC9="","",VLOOKUP(AC9,'PROJECT STAGE'!$A$2:$C$100,3,)) -> TP | AH9: =IF(AI9="","","_") -> _ | AI9: 1 | AJ9: =IF(AK9="","","_") -> _ | AK9: 9 | AL9: =IF(AM9="","","_") -> _ | AM9: Notes_Drawing name | AN9: =IF(AO9=0,"","_") -> _ | AO9: 1 | AP9: =IF(AQ9="","","-") -> - | AQ9: 1 | AS9: =IF(A9="RBDTD-LT", "RBDTDLT","Not LT section__") -> Not LT section__ | AT9: =IF(AU9=0,"",".") | AU9: =IF(O9=0,"No input data",INDEX('DOCUMENT TYPE'!D:D,MATCH(Filename!O9,'DOCUMENT TYPE'!A:A,0))) -> 0 | AV9: =IF(AW9=0,"","-") -> - | AW9: =IF(AC9="PD","PP",IF(AC9="MD","TP",IF(AC9="DTD","DP","Check PROJECT STAGE"))) -> Check PROJECT STAGE | AX9: =IF(AY9>"0","-","") -> - | AY9: =IF(AO9=0,"",TEXT(AO9,"00")) -> 01 | AZ9: =IF(BA9>"0","-","") -> - | BA9: =IF(AQ9=0,"",TEXT(AQ9,"00")) -> 01 | BC9: =IF(Y9="","Missing input data",IF(Y9="-","Missing input data",_xlfn.TEXTJOIN(,,C9,E9,I9,AF9,AG9,X9,Y9,R9:S9,AP9,(TEXT(AQ9,"00")),AJ9,(TEXT(AK9,"v00")),AL9:AM9))) -> DS1DPS1CU102002_TP-VK-1-01_v09_Notes_Drawing name | BD9: =IF(Y9="","Missing input data",IF(Y9="-","Missing input data",LEN(BC9))) -> 49 | BF9: =IF(AA9="","Missing input data",IF(AA9="-","Missing input data",_xlfn.TEXTJOIN(,,A9:E9,AF9,AG9,P9,AA9,R9:S9,AP9,(TEXT(AQ9,"00")),AJ9,(TEXT(AK9,"v00")),AL9:AM9))) -> RBDTD-EE-DS1-DPS1_TP-DR-1-01_v09_Notes_Drawing name | BG9: =IF(AA9="","Missing input data",IF(AA9="-","Missing input data",LEN(BF9))) -> 51 | BI9: =IF(W9="","Missing input data",IF(W9="-","Missing input data",_xlfn.TEXTJOIN(,,A9:N9,Q9,T9,W9:Y9,AB9,AE9,AH9,(TEXT(AI9,"000000")),AL9:AM9))) -> RBDTD-EE-DS1-DPS1_VER_CU102002-ZZ_ZZZZ_SU_DR-VK_DTD_000001_Notes_Drawing name | BJ9: =IF(W9="","Missing input data",IF(W9="-","Missing input data",LEN(BI9))) -> 77 | BL9: =IF(W9="","Missing input data",IF(W9="-","Missing input data",_xlfn.TEXTJOIN(,,A9:N9,Q9,T9,W9:Y9,AB9,AE9,AH9,(TEXT(AI9,"000000")),AJ9,(TEXT(AK9,"000"))))) -> RBDTD-EE-DS1-DPS1_VER_CU102002-ZZ_ZZZZ_SU_DR-VK_DTD_000001_009 | BM9: =IF(W9="","Missing input data",IF(W9="-","Missing input data",LEN(BL9))) -> 62
B10: =IF(C10=0,"","-") | D10: =IF(E10=0,"","-") | F10: =IF(G10=0,"","_") | H10: =IF(I10=0,"","_") | J10: =IF(K10=0,"","-") | L10: =IF(M10=0,"","_") | N10: =IF(O10=0,"","_") | P10: =IF(Q10="","","-") | Q10: =IF(O10="","",VLOOKUP(O10,'DOCUMENT TYPE'!$A$2:$D$805,2,)) | R10: =IF(S10="","","-") | S10: =IF(O10="","",VLOOKUP(O10,'DOCUMENT TYPE'!$A$2:$D$805,3,)) | T10: =IF(U10=0,"","_") | V10: =IF(W10="","","-") | W10: =IF(U10="","",VLOOKUP(U10,'ACTIVITY & DISCIPLINE CODE'!$F$3:$I$1863,2,)) | X10: =IF(Y10="","","-") | Y10: =IF(U10="","",VLOOKUP(U10,'ACTIVITY & DISCIPLINE CODE'!$F$3:$I$1863,3,)) | Z10: =IF(AA10="","","_") | AA10: =IF(U10="","",VLOOKUP(U10,'ACTIVITY & DISCIPLINE CODE'!$F$3:$I$1863,4,)) | AB10: =IF(AC10=0,"","_") | AD10: =IF(AE10="","","-") | AE10: =IF(AC10="","",VLOOKUP(AC10,'PROJECT STAGE'!$A$2:$C$100,2,)) | AF10: =IF(AG10="","","_") | AG10: =IF(AC10="","",VLOOKUP(AC10,'PROJECT STAGE'!$A$2:$C$100,3,)) | AH10: =IF(AI10="","","_") | AJ10: =IF(AK10="","","_") | AL10: =IF(AM10="","","_") | AN10: =IF(AO10=0,"","_") -> _ | AO10: 2 | AP10: =IF(AQ10="","","-") | AS10: =IF(A10="RBDTD-LT", "RBDTDLT","Not LT section") -> Not LT section | AT10: =IF(AU10=0,"",".") -> . | AU10: =IF(O10=0,"No input data",INDEX('DOCUMENT TYPE'!D:D,MATCH(Filename!O10,'DOCUMENT TYPE'!A:A,0))) -> No input data | AV10: =IF(AW10=0,"","-") -> - | AW10: =IF(AC10="PD","PP",IF(AC10="MD","TP",IF(AC10="DTD","DP","Check PROJECT STAGE"))) -> Check PROJECT STAGE | AX10: =IF(AY10>"0","-","") -> - | AY10: =IF(AO10=0,"",TEXT(AO10,"00")) -> 02 | AZ10: =IF(BA10>"0","-","") | BA10: =IF(AQ10=0,"",TEXT(AQ10,"00")) | BC10: =IF(Y10="","Missing input data",IF(Y10="-","Missing input data",_xlfn.TEXTJOIN(,,A10:E10,AF10,AG10,P10,Y10,R10:S10,AP10,(TEXT(AQ10,"00")),AJ10,(TEXT(AK10,"v00")),AL10:AM10))) -> Missing input data | BD10: =IF(Y10="","Missing input data",IF(Y10="-","Missing input data",LEN(BC10))) -> Missing input data | BF10: =IF(AA10="","Missing input data",IF(AA10="-","Missing input data",_xlfn.TEXTJOIN(,,A10:E10,AF10,AG10,P10,AA10,R10:S10,AP10,(TEXT(AQ10,"00")),AJ10,(TEXT(AK10,"v00")),AL10:AM10))) -> Missing input data | BG10: =IF(AA10="","Missing input data",IF(AA10="-","Missing input data",LEN(BF10))) -> Missing input data | BI10: =IF(W10="","Missing input data",IF(W10="-","Missing input data",_xlfn.TEXTJOIN(,,A10:N10,Q10,T10,W10:Y10,AB10,AE10,AH10,(TEXT(AI10,"000000")),AL10:AM10))) -> Missing input data | BJ10: =IF(W10="","Missing input data",IF(W10="-","Missing input data",LEN(BI10))) -> Missing input data | BL10: =IF(W10="","Missing input data",IF(W10="-","Missing input data",_xlfn.TEXTJOIN(,,A10:N10,Q10,T10,W10:Y10,AB10,AE10,AH10,(TEXT(AI10,"000000")),AJ10,(TEXT(AK10,"000"))))) -> Missing input data | BM10: =IF(W10="","Missing input data",IF(W10="-","Missing input data",LEN(BL10))) -> Missing input data
B11: =IF(C11=0,"","-") | D11: =IF(E11=0,"","-") | F11: =IF(G11=0,"","_") | H11: =IF(I11=0,"","_") | J11: =IF(K11=0,"","-") | L11: =IF(M11=0,"","_") | N11: =IF(O11=0,"","_") | P11: =IF(Q11="","","-") | Q11: =IF(O11="","",VLOOKUP(O11,'DOCUMENT TYPE'!$A$2:$D$805,2,)) | R11: =IF(S11="","","-") | S11: =IF(O11="","",VLOOKUP(O11,'DOCUMENT TYPE'!$A$2:$D$805,3,)) | T11: =IF(U11=0,"","_") | V11: =IF(W11="","","-") | W11: =IF(U11="","",VLOOKUP(U11,'ACTIVITY & DISCIPLINE CODE'!$F$3:$I$1863,2,)) | X11: =IF(Y11="","","-") | Y11: =IF(U11="","",VLOOKUP(U11,'ACTIVITY & DISCIPLINE CODE'!$F$3:$I$1863,3,)) | Z11: =IF(AA11="","","_") | AA11: =IF(U11="","",VLOOKUP(U11,'ACTIVITY & DISCIPLINE CODE'!$F$3:$I$1863,4,)) | AB11: =IF(AC11=0,"","_") | AD11: =IF(AE11="","","-") | AE11: =IF(AC11="","",VLOOKUP(AC11,'PROJECT STAGE'!$A$2:$C$100,2,)) | AF11: =IF(AG11="","","_") | AG11: =IF(AC11="","",VLOOKUP(AC11,'PROJECT STAGE'!$A$2:$C$100,3,)) | AH11: =IF(AI11="","","_") | AJ11: =IF(AK11="","","_") | AL11: =IF(AM11="","","_") | AN11: =IF(AO11=0,"","_") | AP11: =IF(AQ11="","","-") | AS11: =IF(A11="RBDTD-LT", "RBDTDLT","Not LT section") -> Not LT section | AT11: =IF(AU11=0,"",".") -> . | AU11: =IF(O11=0,"No input data",INDEX('DOCUMENT TYPE'!D:D,MATCH(Filename!O11,'DOCUMENT TYPE'!A:A,0))) -> No input data | AV11: =IF(AW11=0,"","-") -> - | AW11: =IF(AC11="PD","PP",IF(AC11="MD","TP",IF(AC11="DTD","DP","Check PROJECT STAGE"))) -> Check PROJECT STAGE | AX11: =IF(AY11>"0","-","") | AY11: =IF(AO11=0,"",TEXT(AO11,"00")) | AZ11: =IF(BA11>"0","-","") | BA11: =IF(AQ11=0,"",TEXT(AQ11,"00")) | BC11: =IF(Y11="","Missing input data",IF(Y11="-","Missing input data",_xlfn.TEXTJOIN(,,A11:E11,AF11,AG11,P11,Y11,R11:S11,AP11,(TEXT(AQ11,"00")),AJ11,(TEXT(AK11,"v00")),AL11:AM11))) -> Missing input data | BD11: =IF(Y11="","Missing input data",IF(Y11="-","Missing input data",LEN(BC11))) -> Missing input data | BF11: =IF(AA11="","Missing input data",IF(AA11="-","Missing input data",_xlfn.TEXTJOIN(,,A11:E11,AF11,AG11,P11,AA11,R11:S11,AP11,(TEXT(AQ11,"00")),AJ11,(TEXT(AK11,"v00")),AL11:AM11))) -> Missing input data | BG11: =IF(AA11="","Missing input data",IF(AA11="-","Missing input data",LEN(BF11))) -> Missing input data | BI11: =IF(W11="","Missing input data",IF(W11="-","Missing input data",_xlfn.TEXTJOIN(,,A11:N11,Q11,T11,W11:Y11,AB11,AE11,AH11,(TEXT(AI11,"000000")),AL11:AM11))) -> Missing input data | BJ11: =IF(W11="","Missing input data",IF(W11="-","Missing input data",LEN(BI11))) -> Missing input data | BL11: =IF(W11="","Missing input data",IF(W11="-","Missing input data",_xlfn.TEXTJOIN(,,A11:N11,Q11,T11,W11:Y11,AB11,AE11,AH11,(TEXT(AI11,"000000")),AJ11,(TEXT(AK11,"000"))))) -> Missing input data | BM11: =IF(W11="","Missing input data",IF(W11="-","Missing input data",LEN(BL11))) -> Missing input data
B12: =IF(C12=0,"","-") | D12: =IF(E12=0,"","-") | F12: =IF(G12=0,"","_") | H12: =IF(I12=0,"","_") | J12: =IF(K12=0,"","-") | L12: =IF(M12=0,"","_") | N12: =IF(O12=0,"","_") | P12: =IF(Q12="","","-") | Q12: =IF(O12="","",VLOOKUP(O12,'DOCUMENT TYPE'!$A$2:$D$805,2,)) | R12: =IF(S12="","","-") | S12: =IF(O12="","",VLOOKUP(O12,'DOCUMENT TYPE'!$A$2:$D$805,3,)) | T12: =IF(U12=0,"","_") | V12: =IF(W12="","","-") | W12: =IF(U12="","",VLOOKUP(U12,'ACTIVITY & DISCIPLINE CODE'!$F$3:$I$1863,2,)) | X12: =IF(Y12="","","-") | Y12: =IF(U12="","",VLOOKUP(U12,'ACTIVITY & DISCIPLINE CODE'!$F$3:$I$1863,3,)) | Z12: =IF(AA12="","","_") | AA12: =IF(U12="","",VLOOKUP(U12,'ACTIVITY & DISCIPLINE CODE'!$F$3:$I$1863,4,)) | AB12: =IF(AC12=0,"","_") | AD12: =IF(AE12="","","-") | AE12: =IF(AC12="","",VLOOKUP(AC12,'PROJECT STAGE'!$A$2:$C$100,2,)) | AF12: =IF(AG12="","","_") | AG12: =IF(AC12="","",VLOOKUP(AC12,'PROJECT STAGE'!$A$2:$C$100,3,)) | AH12: =IF(AI12="","","_") | AJ12: =IF(AK12="","","_") | AL12: =IF(AM12="","","_") | AN12: =IF(AO12=0,"","_") | AP12: =IF(AQ12="","","-") | AS12: =IF(A12="RBDTD-LT", "RBDTDLT","Not LT section") -> Not LT section | AT12: =IF(AU12=0,"",".") -> . | AU12: =IF(O12=0,"No input data",INDEX('DOCUMENT TYPE'!D:D,MATCH(Filename!O12,'DOCUMENT TYPE'!A:A,0))) -> No input data | AV12: =IF(AW12=0,"","-") -> - | AW12: =IF(AC12="PD","PP",IF(AC12="MD","TP",IF(AC12="DTD","DP","Check PROJECT STAGE"))) -> Check PROJECT STAGE | AX12: =IF(AY12>"0","-","") | AY12: =IF(AO12=0,"",TEXT(AO12,"00")) | AZ12: =IF(BA12>"0","-","") | BA12: =IF(AQ12=0,"",TEXT(AQ12,"00")) | BC12: =IF(Y12="","Missing input data",IF(Y12="-","Missing input data",_xlfn.TEXTJOIN(,,A12:E12,AF12,AG12,P12,Y12,R12:S12,AP12,(TEXT(AQ12,"00")),AJ12,(TEXT(AK12,"v00")),AL12:AM12))) -> Missing input data | BD12: =IF(Y12="","Missing input data",IF(Y12="-","Missing input data",LEN(BC12))) -> Missing input data | BF12: =IF(AA12="","Missing input data",IF(AA12="-","Missing input data",_xlfn.TEXTJOIN(,,A12:E12,AF12,AG12,P12,AA12,R12:S12,AP12,(TEXT(AQ12,"00")),AJ12,(TEXT(AK12,"v00")),AL12:AM12))) -> Missing input data | BG12: =IF(AA12="","Missing input data",IF(AA12="-","Missing input data",LEN(BF12))) -> Missing input data | BI12: =IF(W12="","Missing input data",IF(W12="-","Missing input data",_xlfn.TEXTJOIN(,,A12:N12,Q12,T12,W12:Y12,AB12,AE12,AH12,(TEXT(AI12,"000000")),AL12:AM12))) -> Missing input data | BJ12: =IF(W12="","Missing input data",IF(W12="-","Missing input data",LEN(BI12))) -> Missing input data | BL12: =IF(W12="","Missing input data",IF(W12="-","Missing input data",_xlfn.TEXTJOIN(,,A12:N12,Q12,T12,W12:Y12,AB12,AE12,AH12,(TEXT(AI12,"000000")),AJ12,(TEXT(AK12,"000"))))) -> Missing input data | BM12: =IF(W12="","Missing input data",IF(W12="-","Missing input data",LEN(BL12))) -> Missing input data
B13: =IF(C13=0,"","-") | D13: =IF(E13=0,"","-") | F13: =IF(G13=0,"","_") | H13: =IF(I13=0,"","_") | J13: =IF(K13=0,"","-") | L13: =IF(M13=0,"","_") | N13: =IF(O13=0,"","_") | P13: =IF(Q13="","","-") | Q13: =IF(O13="","",VLOOKUP(O13,'DOCUMENT TYPE'!$A$2:$D$805,2,)) | R13: =IF(S13="","","-") | S13: =IF(O13="","",VLOOKUP(O13,'DOCUMENT TYPE'!$A$2:$D$805,3,)) | T13: =IF(U13=0,"","_") | V13: =IF(W13="","","-") | W13: =IF(U13="","",VLOOKUP(U13,'ACTIVITY & DISCIPLINE CODE'!$F$3:$I$1863,2,)) | X13: =IF(Y13="","","-") | Y13: =IF(U13="","",VLOOKUP(U13,'ACTIVITY & DISCIPLINE CODE'!$F$3:$I$1863,3,)) | Z13: =IF(AA13="","","_") | AA13: =IF(U13="","",VLOOKUP(U13,'ACTIVITY & DISCIPLINE CODE'!$F$3:$I$1863,4,)) | AB13: =IF(AC13=0,"","_") | AD13: =IF(AE13="","","-") | AE13: =IF(AC13="","",VLOOKUP(AC13,'PROJECT STAGE'!$A$2:$C$100,2,)) | AF13: =IF(AG13="","","_") | AG13: =IF(AC13="","",VLOOKUP(AC13,'PROJECT STAGE'!$A$2:$C$100,3,)) | AH13: =IF(AI13="","","_") | AJ13: =IF(AK13="","","_") | AL13: =IF(AM13="","","_") | AN13: =IF(AO13=0,"","_") | AP13: =IF(AQ13="","","-") | AS13: =IF(A13="RBDTD-LT", "RBDTDLT","Not LT section") -> Not LT section | AT13: =IF(AU13=0,"",".") -> . | AU13: =IF(O13=0,"No input data",INDEX('DOCUMENT TYPE'!D:D,MATCH(Filename!O13,'DOCUMENT TYPE'!A:A,0))) -> No input data | AV13: =IF(AW13=0,"","-") -> - | AW13: =IF(AC13="PD","PP",IF(AC13="MD","TP",IF(AC13="DTD","DP","Check PROJECT STAGE"))) -> Check PROJECT STAGE | AX13: =IF(AY13>"0","-","") | AY13: =IF(AO13=0,"",TEXT(AO13,"00")) | AZ13: =IF(BA13>"0","-","") | BA13: =IF(AQ13=0,"",TEXT(AQ13,"00")) | BC13: =IF(Y13="","Missing input data",IF(Y13="-","Missing input data",_xlfn.TEXTJOIN(,,A13:E13,AF13,AG13,P13,Y13,R13:S13,AP13,(TEXT(AQ13,"00")),AJ13,(TEXT(AK13,"v00")),AL13:AM13))) -> Missing input data | BD13: =IF(Y13="","Missing input data",IF(Y13="-","Missing input data",LEN(BC13))) -> Missing input data | BF13: =IF(AA13="","Missing input data",IF(AA13="-","Missing input data",_xlfn.TEXTJOIN(,,A13:E13,AF13,AG13,P13,AA13,R13:S13,AP13,(TEXT(AQ13,"00")),AJ13,(TEXT(AK13,"v00")),AL13:AM13))) -> Missing input data | BG13: =IF(AA13="","Missing input data",IF(AA13="-","Missing input data",LEN(BF13))) -> Missing input data | BI13: =IF(W13="","Missing input data",IF(W13="-","Missing input data",_xlfn.TEXTJOIN(,,A13:N13,Q13,T13,W13:Y13,AB13,AE13,AH13,(TEXT(AI13,"000000")),AL13:AM13))) -> Missing input data | BJ13: =IF(W13="","Missing input data",IF(W13="-","Missing input data",LEN(BI13))) -> Missing input data | BL13: =IF(W13="","Missing input data",IF(W13="-","Missing input data",_xlfn.TEXTJOIN(,,A13:N13,Q13,T13,W13:Y13,AB13,AE13,AH13,(TEXT(AI13,"000000")),AJ13,(TEXT(AK13,"000"))))) -> Missing input data | BM13: =IF(W13="","Missing input data",IF(W13="-","Missing input data",LEN(BL13))) -> Missing input data
B14: =IF(C14=0,"","-") | D14: =IF(E14=0,"","-") | F14: =IF(G14=0,"","_") | H14: =IF(I14=0,"","_") | J14: =IF(K14=0,"","-") | L14: =IF(M14=0,"","_") | N14: =IF(O14=0,"","_") | P14: =IF(Q14="","","-") | Q14: =IF(O14="","",VLOOKUP(O14,'DOCUMENT TYPE'!$A$2:$D$805,2,)) | R14: =IF(S14="","","-") | S14: =IF(O14="","",VLOOKUP(O14,'DOCUMENT TYPE'!$A$2:$D$805,3,)) | T14: =IF(U14=0,"","_") | V14: =IF(W14="","","-") | W14: =IF(U14="","",VLOOKUP(U14,'ACTIVITY & DISCIPLINE CODE'!$F$3:$I$1863,2,)) | X14: =IF(Y14="","","-") | Y14: =IF(U14="","",VLOOKUP(U14,'ACTIVITY & DISCIPLINE CODE'!$F$3:$I$1863,3,)) | Z14: =IF(AA14="","","_") | AA14: =IF(U14="","",VLOOKUP(U14,'ACTIVITY & DISCIPLINE CODE'!$F$3:$I$1863,4,)) | AB14: =IF(AC14=0,"","_") | AD14: =IF(AE14="","","-") | AE14: =IF(AC14="","",VLOOKUP(AC14,'PROJECT STAGE'!$A$2:$C$100,2,)) | AF14: =IF(AG14="","","_") | AG14: =IF(AC14="","",VLOOKUP(AC14,'PROJECT STAGE'!$A$2:$C$100,3,)) | AH14: =IF(AI14="","","_") | AJ14: =IF(AK14="","","_") | AL14: =IF(AM14="","","_") | AN14: =IF(AO14=0,"","_") | AP14: =IF(AQ14="","","-") | AS14: =IF(A14="RBDTD-LT", "RBDTDLT","Not LT section") -> Not LT section | AT14: =IF(AU14=0,"",".") -> . | AU14: =IF(O14=0,"No input data",INDEX('DOCUMENT TYPE'!D:D,MATCH(Filename!O14,'DOCUMENT TYPE'!A:A,0))) -> No input data | AV14: =IF(AW14=0,"","-") -> - | AW14: =IF(AC14="PD","PP",IF(AC14="MD","TP",IF(AC14="DTD","DP","Check PROJECT STAGE"))) -> Check PROJECT STAGE | AX14: =IF(AY14>"0","-","") | AY14: =IF(AO14=0,"",TEXT(AO14,"00")) | AZ14: =IF(BA14>"0","-","") | BA14: =IF(AQ14=0,"",TEXT(AQ14,"00")) | BC14: =IF(Y14="","Missing input data",IF(Y14="-","Missing input data",_xlfn.TEXTJOIN(,,A14:E14,AF14,AG14,P14,Y14,R14:S14,AP14,(TEXT(AQ14,"00")),AJ14,(TEXT(AK14,"v00")),AL14:AM14))) -> Missing input data | BD14: =IF(Y14="","Missing input data",IF(Y14="-","Missing input data",LEN(BC14))) -> Missing input data | BF14: =IF(AA14="","Missing input data",IF(AA14="-","Missing input data",_xlfn.TEXTJOIN(,,A14:E14,AF14,AG14,P14,AA14,R14:S14,AP14,(TEXT(AQ14,"00")),AJ14,(TEXT(AK14,"v00")),AL14:AM14))) -> Missing input data | BG14: =IF(AA14="","Missing input data",IF(AA14="-","Missing input data",LEN(BF14))) -> Missing input data | BI14: =IF(W14="","Missing input data",IF(W14="-","Missing input data",_xlfn.TEXTJOIN(,,A14:N14,Q14,T14,W14:Y14,AB14,AE14,AH14,(TEXT(AI14,"000000")),AL14:AM14))) -> Missing input data | BJ14: =IF(W14="","Missing input data",IF(W14="-","Missing input data",LEN(BI14))) -> Missing input data | BL14: =IF(W14="","Missing input data",IF(W14="-","Missing input data",_xlfn.TEXTJOIN(,,A14:N14,Q14,T14,W14:Y14,AB14,AE14,AH14,(TEXT(AI14,"000000")),AJ14,(TEXT(AK14,"000"))))) -> Missing input data | BM14: =IF(W14="","Missing input data",IF(W14="-","Missing input data",LEN(BL14))) -> Missing input data
B15: =IF(C15=0,"","-") | D15: =IF(E15=0,"","-") | F15: =IF(G15=0,"","_") | H15: =IF(I15=0,"","_") | J15: =IF(K15=0,"","-") | L15: =IF(M15=0,"","_") | N15: =IF(O15=0,"","_") | P15: =IF(Q15="","","-") | Q15: =IF(O15="","",VLOOKUP(O15,'DOCUMENT TYPE'!$A$2:$D$805,2,)) | R15: =IF(S15="","","-") | S15: =IF(O15="","",VLOOKUP(O15,'DOCUMENT TYPE'!$A$2:$D$805,3,)) | T15: =IF(U15=0,"","_") | V15: =IF(W15="","","-") | W15: =IF(U15="","",VLOOKUP(U15,'ACTIVITY & DISCIPLINE CODE'!$F$3:$I$1863,2,)) | X15: =IF(Y15="","","-") | Y15: =IF(U15="","",VLOOKUP(U15,'ACTIVITY & DISCIPLINE CODE'!$F$3:$I$1863,3,)) | Z15: =IF(AA15="","","_") | AA15: =IF(U15="","",VLOOKUP(U15,'ACTIVITY & DISCIPLINE CODE'!$F$3:$I$1863,4,)) | AB15: =IF(AC15=0,"","_") | AD15: =IF(AE15="","","-") | AE15: =IF(AC15="","",VLOOKUP(AC15,'PROJECT STAGE'!$A$2:$C$100,2,)) | AF15: =IF(AG15="","","_") | AG15: =IF(AC15="","",VLOOKUP(AC15,'PROJECT STAGE'!$A$2:$C$100,3,)) | AH15: =IF(AI15="","","_") | AJ15: =IF(AK15="","","_") | AL15: =IF(AM15="","","_") | AN15: =IF(AO15=0,"","_") | AP15: =IF(AQ15="","","-") | AS15: =IF(A15="RBDTD-LT", "RBDTDLT","Not LT section") -> Not LT section | AT15: =IF(AU15=0,"",".") -> . | AU15: =IF(O15=0,"No input data",INDEX('DOCUMENT TYPE'!D:D,MATCH(Filename!O15,'DOCUMENT TYPE'!A:A,0))) -> No input data | AV15: =IF(AW15=0,"","-") -> - | AW15: =IF(AC15="PD","PP",IF(AC15="MD","TP",IF(AC15="DTD","DP","Check PROJECT STAGE"))) -> Check PROJECT STAGE | AX15: =IF(AY15>"0","-","") | AY15: =IF(AO15=0,"",TEXT(AO15,"00")) | AZ15: =IF(BA15>"0","-","") | BA15: =IF(AQ15=0,"",TEXT(AQ15,"00")) | BC15: =IF(Y15="","Missing input data",IF(Y15="-","Missing input data",_xlfn.TEXTJOIN(,,A15:E15,AF15,AG15,P15,Y15,R15:S15,AP15,(TEXT(AQ15,"00")),AJ15,(TEXT(AK15,"v00")),AL15:AM15))) -> Missing input data | BD15: =IF(Y15="","Missing input data",IF(Y15="-","Missing input data",LEN(BC15))) -> Missing input data | BF15: =IF(AA15="","Missing input data",IF(AA15="-","Missing input data",_xlfn.TEXTJOIN(,,A15:E15,AF15,AG15,P15,AA15,R15:S15,AP15,(TEXT(AQ15,"00")),AJ15,(TEXT(AK15,"v00")),AL15:AM15))) -> Missing input data | BG15: =IF(AA15="","Missing input data",IF(AA15="-","Missing input data",LEN(BF15))) -> Missing input data | BI15: =IF(W15="","Missing input data",IF(W15="-","Missing input data",_xlfn.TEXTJOIN(,,A15:N15,Q15,T15,W15:Y15,AB15,AE15,AH15,(TEXT(AI15,"000000")),AL15:AM15))) -> Missing input data | BJ15: =IF(W15="","Missing input data",IF(W15="-","Missing input data",LEN(BI15))) -> Missing input data | BL15: =IF(W15="","Missing input data",IF(W15="-","Missing input data",_xlfn.TEXTJOIN(,,A15:N15,Q15,T15,W15:Y15,AB15,AE15,AH15,(TEXT(AI15,"000000")),AJ15,(TEXT(AK15,"000"))))) -> Missing input data | BM15: =IF(W15="","Missing input data",IF(W15="-","Missing input data",LEN(BL15))) -> Missing input data
B16: =IF(C16=0,"","-") | D16: =IF(E16=0,"","-") | F16: =IF(G16=0,"","_") | H16: =IF(I16=0,"","_") | J16: =IF(K16=0,"","-") | L16: =IF(M16=0,"","_") | N16: =IF(O16=0,"","_") | P16: =IF(Q16="","","-") | Q16: =IF(O16="","",VLOOKUP(O16,'DOCUMENT TYPE'!$A$2:$D$805,2,)) | R16: =IF(S16="","","-") | S16: =IF(O16="","",VLOOKUP(O16,'DOCUMENT TYPE'!$A$2:$D$805,3,)) | T16: =IF(U16=0,"","_") | V16: =IF(W16="","","-") | W16: =IF(U16="","",VLOOKUP(U16,'ACTIVITY & DISCIPLINE CODE'!$F$3:$I$1863,2,)) | X16: =IF(Y16="","","-") | Y16: =IF(U16="","",VLOOKUP(U16,'ACTIVITY & DISCIPLINE CODE'!$F$3:$I$1863,3,)) | Z16: =IF(AA16="","","_") | AA16: =IF(U16="","",VLOOKUP(U16,'ACTIVITY & DISCIPLINE CODE'!$F$3:$I$1863,4,)) | AB16: =IF(AC16=0,"","_") | AD16: =IF(AE16="","","-") | AE16: =IF(AC16="","",VLOOKUP(AC16,'PROJECT STAGE'!$A$2:$C$100,2,)) | AF16: =IF(AG16="","","_") | AG16: =IF(AC16="","",VLOOKUP(AC16,'PROJECT STAGE'!$A$2:$C$100,3,)) | AH16: =IF(AI16="","","_") | AJ16: =IF(AK16="","","_") | AL16: =IF(AM16="","","_") | AN16: =IF(AO16=0,"","_") | AP16: =IF(AQ16="","","-") | AS16: =IF(A16="RBDTD-LT", "RBDTDLT","Not LT section") -> Not LT section | AT16: =IF(AU16=0,"",".") -> . | AU16: =IF(O16=0,"No input data",INDEX('DOCUMENT TYPE'!D:D,MATCH(Filename!O16,'DOCUMENT TYPE'!A:A,0))) -> No input data | AV16: =IF(AW16=0,"","-") -> - | AW16: =IF(AC16="PD","PP",IF(AC16="MD","TP",IF(AC16="DTD","DP","Check PROJECT STAGE"))) -> Check PROJECT STAGE | AX16: =IF(AY16>"0","-","") | AY16: =IF(AO16=0,"",TEXT(AO16,"00")) | AZ16: =IF(BA16>"0","-","") | BA16: =IF(AQ16=0,"",TEXT(AQ16,"00")) | BC16: =IF(Y16="","Missing input data",IF(Y16="-","Missing input data",_xlfn.TEXTJOIN(,,A16:E16,AF16,AG16,P16,Y16,R16:S16,AP16,(TEXT(AQ16,"00")),AJ16,(TEXT(AK16,"v00")),AL16:AM16))) -> Missing input data | BD16: =IF(Y16="","Missing input data",IF(Y16="-","Missing input data",LEN(BC16))) -> Missing input data | BF16: =IF(AA16="","Missing input data",IF(AA16="-","Missing input data",_xlfn.TEXTJOIN(,,A16:E16,AF16,AG16,P16,AA16,R16:S16,AP16,(TEXT(AQ16,"00")),AJ16,(TEXT(AK16,"v00")),AL16:AM16))) -> Missing input data | BG16: =IF(AA16="","Missing input data",IF(AA16="-","Missing input data",LEN(BF16))) -> Missing input data | BI16: =IF(W16="","Missing input data",IF(W16="-","Missing input data",_xlfn.TEXTJOIN(,,A16:N16,Q16,T16,W16:Y16,AB16,AE16,AH16,(TEXT(AI16,"000000")),AL16:AM16))) -> Missing input data | BJ16: =IF(W16="","Missing input data",IF(W16="-","Missing input data",LEN(BI16))) -> Missing input data | BL16: =IF(W16="","Missing input data",IF(W16="-","Missing input data",_xlfn.TEXTJOIN(,,A16:N16,Q16,T16,W16:Y16,AB16,AE16,AH16,(TEXT(AI16,"000000")),AJ16,(TEXT(AK16,"000"))))) -> Missing input data | BM16: =IF(W16="","Missing input data",IF(W16="-","Missing input data",LEN(BL16))) -> Missing input data
B17: =IF(C17=0,"","-") | D17: =IF(E17=0,"","-") | F17: =IF(G17=0,"","_") | H17: =IF(I17=0,"","_") | J17: =IF(K17=0,"","-") | L17: =IF(M17=0,"","_") | N17: =IF(O17=0,"","_") | P17: =IF(Q17="","","-") | Q17: =IF(O17="","",VLOOKUP(O17,'DOCUMENT TYPE'!$A$2:$D$805,2,)) | R17: =IF(S17="","","-") | S17: =IF(O17="","",VLOOKUP(O17,'DOCUMENT TYPE'!$A$2:$D$805,3,)) | T17: =IF(U17=0,"","_") | V17: =IF(W17="","","-") | W17: =IF(U17="","",VLOOKUP(U17,'ACTIVITY & DISCIPLINE CODE'!$F$3:$I$1863,2,)) | X17: =IF(Y17="","","-") | Y17: =IF(U17="","",VLOOKUP(U17,'ACTIVITY & DISCIPLINE CODE'!$F$3:$I$1863,3,)) | Z17: =IF(AA17="","","_") | AA17: =IF(U17="","",VLOOKUP(U17,'ACTIVITY & DISCIPLINE CODE'!$F$3:$I$1863,4,)) | AB17: =IF(AC17=0,"","_") | AD17: =IF(AE17="","","-") | AE17: =IF(AC17="","",VLOOKUP(AC17,'PROJECT STAGE'!$A$2:$C$100,2,)) | AF17: =IF(AG17="","","_") | AG17: =IF(AC17="","",VLOOKUP(AC17,'PROJECT STAGE'!$A$2:$C$100,3,)) | AH17: =IF(AI17="","","_") | AJ17: =IF(AK17="","","_") | AL17: =IF(AM17="","","_") | AN17: =IF(AO17=0,"","_") | AP17: =IF(AQ17="","","-") | AS17: =IF(A17="RBDTD-LT", "RBDTDLT","Not LT section") -> Not LT section | AT17: =IF(AU17=0,"",".") -> . | AU17: =IF(O17=0,"No input data",INDEX('DOCUMENT TYPE'!D:D,MATCH(Filename!O17,'DOCUMENT TYPE'!A:A,0))) -> No input data | AV17: =IF(AW17=0,"","-") -> - | AW17: =IF(AC17="PD","PP",IF(AC17="MD","TP",IF(AC17="DTD","DP","Check PROJECT STAGE"))) -> Check PROJECT STAGE | AX17: =IF(AY17>"0","-","") | AY17: =IF(AO17=0,"",TEXT(AO17,"00")) | AZ17: =IF(BA17>"0","-","") | BA17: =IF(AQ17=0,"",TEXT(AQ17,"00")) | BC17: =IF(Y17="","Missing input data",IF(Y17="-","Missing input data",_xlfn.TEXTJOIN(,,A17:E17,AF17,AG17,P17,Y17,R17:S17,AP17,(TEXT(AQ17,"00")),AJ17,(TEXT(AK17,"v00")),AL17:AM17))) -> Missing input data | BD17: =IF(Y17="","Missing input data",IF(Y17="-","Missing input data",LEN(BC17))) -> Missing input data | BF17: =IF(AA17="","Missing input data",IF(AA17="-","Missing input data",_xlfn.TEXTJOIN(,,A17:E17,AF17,AG17,P17,AA17,R17:S17,AP17,(TEXT(AQ17,"00")),AJ17,(TEXT(AK17,"v00")),AL17:AM17))) -> Missing input data | BG17: =IF(AA17="","Missing input data",IF(AA17="-","Missing input data",LEN(BF17))) -> Missing input data | BI17: =IF(W17="","Missing input data",IF(W17="-","Missing input data",_xlfn.TEXTJOIN(,,A17:N17,Q17,T17,W17:Y17,AB17,AE17,AH17,(TEXT(AI17,"000000")),AL17:AM17))) -> Missing input data | BJ17: =IF(W17="","Missing input data",IF(W17="-","Missing input data",LEN(BI17))) -> Missing input data | BL17: =IF(W17="","Missing input data",IF(W17="-","Missing input data",_xlfn.TEXTJOIN(,,A17:N17,Q17,T17,W17:Y17,AB17,AE17,AH17,(TEXT(AI17,"000000")),AJ17,(TEXT(AK17,"000"))))) -> Missing input data | BM17: =IF(W17="","Missing input data",IF(W17="-","Missing input data",LEN(BL17))) -> Missing input data
B18: =IF(C18=0,"","-") | D18: =IF(E18=0,"","-") | F18: =IF(G18=0,"","_") | H18: =IF(I18=0,"","_") | J18: =IF(K18=0,"","-") | L18: =IF(M18=0,"","_") | N18: =IF(O18=0,"","_") | P18: =IF(Q18="","","-") | Q18: =IF(O18="","",VLOOKUP(O18,'DOCUMENT TYPE'!$A$2:$D$805,2,)) | R18: =IF(S18="","","-") | S18: =IF(O18="","",VLOOKUP(O18,'DOCUMENT TYPE'!$A$2:$D$805,3,)) | T18: =IF(U18=0,"","_") | V18: =IF(W18="","","-") | W18: =IF(U18="","",VLOOKUP(U18,'ACTIVITY & DISCIPLINE CODE'!$F$3:$I$1863,2,)) | X18: =IF(Y18="","","-") | Y18: =IF(U18="","",VLOOKUP(U18,'ACTIVITY & DISCIPLINE CODE'!$F$3:$I$1863,3,)) | Z18: =IF(AA18="","","_") | AA18: =IF(U18="","",VLOOKUP(U18,'ACTIVITY & DISCIPLINE CODE'!$F$3:$I$1863,4,)) | AB18: =IF(AC18=0,"","_") | AD18: =IF(AE18="","","-") | AE18: =IF(AC18="","",VLOOKUP(AC18,'PROJECT STAGE'!$A$2:$C$100,2,)) | AF18: =IF(AG18="","","_") | AG18: =IF(AC18="","",VLOOKUP(AC18,'PROJECT STAGE'!$A$2:$C$100,3,)) | AH18: =IF(AI18="","","_") | AJ18: =IF(AK18="","","_") | AL18: =IF(AM18="","","_") | AN18: =IF(AO18=0,"","_") | AP18: =IF(AQ18="","","-") | AS18: =IF(A18="RBDTD-LT", "RBDTDLT","Not LT section") -> Not LT section | AT18: =IF(AU18=0,"",".") -> . | AU18: =IF(O18=0,"No input data",INDEX('DOCUMENT TYPE'!D:D,MATCH(Filename!O18,'DOCUMENT TYPE'!A:A,0))) -> No input data | AV18: =IF(AW18=0,"","-") -> - | AW18: =IF(AC18="PD","PP",IF(AC18="MD","TP",IF(AC18="DTD","DP","Check PROJECT STAGE"))) -> Check PROJECT STAGE | AX18: =IF(AY18>"0","-","") | AY18: =IF(AO18=0,"",TEXT(AO18,"00")) | AZ18: =IF(BA18>"0","-","") | BA18: =IF(AQ18=0,"",TEXT(AQ18,"00")) | BC18: =IF(Y18="","Missing input data",IF(Y18="-","Missing input data",_xlfn.TEXTJOIN(,,A18:E18,AF18,AG18,P18,Y18,R18:S18,AP18,(TEXT(AQ18,"00")),AJ18,(TEXT(AK18,"v00")),AL18:AM18))) -> Missing input data | BD18: =IF(Y18="","Missing input data",IF(Y18="-","Missing input data",LEN(BC18))) -> Missing input data | BF18: =IF(AA18="","Missing input data",IF(AA18="-","Missing input data",_xlfn.TEXTJOIN(,,A18:E18,AF18,AG18,P18,AA18,R18:S18,AP18,(TEXT(AQ18,"00")),AJ18,(TEXT(AK18,"v00")),AL18:AM18))) -> Missing input data | BG18: =IF(AA18="","Missing input data",IF(AA18="-","Missing input data",LEN(BF18))) -> Missing input data | BI18: =IF(W18="","Missing input data",IF(W18="-","Missing input data",_xlfn.TEXTJOIN(,,A18:N18,Q18,T18,W18:Y18,AB18,AE18,AH18,(TEXT(AI18,"000000")),AL18:AM18))) -> Missing input data | BJ18: =IF(W18="","Missing input data",IF(W18="-","Missing input data",LEN(BI18))) -> Missing input data | BL18: =IF(W18="","Missing input data",IF(W18="-","Missing input data",_xlfn.TEXTJOIN(,,A18:N18,Q18,T18,W18:Y18,AB18,AE18,AH18,(TEXT(AI18,"000000")),AJ18,(TEXT(AK18,"000"))))) -> Missing input data | BM18: =IF(W18="","Missing input data",IF(W18="-","Missing input data",LEN(BL18))) -> Missing input data
B19: =IF(C19=0,"","-") | D19: =IF(E19=0,"","-") | F19: =IF(G19=0,"","_") | H19: =IF(I19=0,"","_") | J19: =IF(K19=0,"","-") | L19: =IF(M19=0,"","_") | N19: =IF(O19=0,"","_") | P19: =IF(Q19="","","-") | Q19: =IF(O19="","",VLOOKUP(O19,'DOCUMENT TYPE'!$A$2:$D$805,2,)) | R19: =IF(S19="","","-") | S19: =IF(O19="","",VLOOKUP(O19,'DOCUMENT TYPE'!$A$2:$D$805,3,)) | T19: =IF(U19=0,"","_") | V19: =IF(W19="","","-") | W19: =IF(U19="","",VLOOKUP(U19,'ACTIVITY & DISCIPLINE CODE'!$F$3:$I$1863,2,)) | X19: =IF(Y19="","","-") | Y19: =IF(U19="","",VLOOKUP(U19,'ACTIVITY & DISCIPLINE CODE'!$F$3:$I$1863,3,)) | Z19: =IF(AA19="","","_") | AA19: =IF(U19="","",VLOOKUP(U19,'ACTIVITY & DISCIPLINE CODE'!$F$3:$I$1863,4,)) | AB19: =IF(AC19=0,"","_") | AD19: =IF(AE19="","","-") | AE19: =IF(AC19="","",VLOOKUP(AC19,'PROJECT STAGE'!$A$2:$C$100,2,)) | AF19: =IF(AG19="","","_") | AG19: =IF(AC19="","",VLOOKUP(AC19,'PROJECT STAGE'!$A$2:$C$100,3,)) | AH19: =IF(AI19="","","_") | AJ19: =IF(AK19="","","_") | AL19: =IF(AM19="","","_") | AN19: =IF(AO19=0,"","_") | AP19: =IF(AQ19="","","-") | AS19: =IF(A19="RBDTD-LT", "RBDTDLT","Not LT section") -> Not LT section | AT19: =IF(AU19=0,"",".") -> . | AU19: =IF(O19=0,"No input data",INDEX('DOCUMENT TYPE'!D:D,MATCH(Filename!O19,'DOCUMENT TYPE'!A:A,0))) -> No input data | AV19: =IF(AW19=0,"","-") -> - | AW19: =IF(AC19="PD","PP",IF(AC19="MD","TP",IF(AC19="DTD","DP","Check PROJECT STAGE"))) -> Check PROJECT STAGE | AX19: =IF(AY19>"0","-","") | AY19: =IF(AO19=0,"",TEXT(AO19,"00")) | AZ19: =IF(BA19>"0","-","") | BA19: =IF(AQ19=0,"",TEXT(AQ19,"00")) | BC19: =IF(Y19="","Missing input data",IF(Y19="-","Missing input data",_xlfn.TEXTJOIN(,,A19:E19,AF19,AG19,P19,Y19,R19:S19,AP19,(TEXT(AQ19,"00")),AJ19,(TEXT(AK19,"v00")),AL19:AM19))) -> Missing input data | BD19: =IF(Y19="","Missing input data",IF(Y19="-","Missing input data",LEN(BC19))) -> Missing input data | BF19: =IF(AA19="","Missing input data",IF(AA19="-","Missing input data",_xlfn.TEXTJOIN(,,A19:E19,AF19,AG19,P19,AA19,R19:S19,AP19,(TEXT(AQ19,"00")),AJ19,(TEXT(AK19,"v00")),AL19:AM19))) -> Missing input data | BG19: =IF(AA19="","Missing input data",IF(AA19="-","Missing input data",LEN(BF19))) -> Missing input data | BI19: =IF(W19="","Missing input data",IF(W19="-","Missing input data",_xlfn.TEXTJOIN(,,A19:N19,Q19,T19,W19:Y19,AB19,AE19,AH19,(TEXT(AI19,"000000")),AL19:AM19))) -> Missing input data | BJ19: =IF(W19="","Missing input data",IF(W19="-","Missing input data",LEN(BI19))) -> Missing input data | BL19: =IF(W19="","Missing input data",IF(W19="-","Missing input data",_xlfn.TEXTJOIN(,,A19:N19,Q19,T19,W19:Y19,AB19,AE19,AH19,(TEXT(AI19,"000000")),AJ19,(TEXT(AK19,"000"))))) -> Missing input data | BM19: =IF(W19="","Missing input data",IF(W19="-","Missing input data",LEN(BL19))) -> Missing input data
B20: =IF(C20=0,"","-") | D20: =IF(E20=0,"","-") | F20: =IF(G20=0,"","_") | H20: =IF(I20=0,"","_") | J20: =IF(K20=0,"","-") | L20: =IF(M20=0,"","_") | N20: =IF(O20=0,"","_") | P20: =IF(Q20="","","-") | Q20: =IF(O20="","",VLOOKUP(O20,'DOCUMENT TYPE'!$A$2:$D$805,2,)) | R20: =IF(S20="","","-") | S20: =IF(O20="","",VLOOKUP(O20,'DOCUMENT TYPE'!$A$2:$D$805,3,)) | T20: =IF(U20=0,"","_") | V20: =IF(W20="","","-") | W20: =IF(U20="","",VLOOKUP(U20,'ACTIVITY & DISCIPLINE CODE'!$F$3:$I$1863,2,)) | X20: =IF(Y20="","","-") | Y20: =IF(U20="","",VLOOKUP(U20,'ACTIVITY & DISCIPLINE CODE'!$F$3:$I$1863,3,)) | Z20: =IF(AA20="","","_") | AA20: =IF(U20="","",VLOOKUP(U20,'ACTIVITY & DISCIPLINE CODE'!$F$3:$I$1863,4,)) | AB20: =IF(AC20=0,"","_") | AD20: =IF(AE20="","","-") | AE20: =IF(AC20="","",VLOOKUP(AC20,'PROJECT STAGE'!$A$2:$C$100,2,)) | AF20: =IF(AG20="","","_") | AG20: =IF(AC20="","",VLOOKUP(AC20,'PROJECT STAGE'!$A$2:$C$100,3,)) | AH20: =IF(AI20="","","_") | AJ20: =IF(AK20="","","_") | AL20: =IF(AM20="","","_") | AN20: =IF(AO20=0,"","_") | AP20: =IF(AQ20="","","-") | AS20: =IF(A20="RBDTD-LT", "RBDTDLT","Not LT section") -> Not LT section | AT20: =IF(AU20=0,"",".") -> . | AU20: =IF(O20=0,"No input data",INDEX('DOCUMENT TYPE'!D:D,MATCH(Filename!O20,'DOCUMENT TYPE'!A:A,0))) -> No input data | AV20: =IF(AW20=0,"","-") -> - | AW20: =IF(AC20="PD","PP",IF(AC20="MD","TP",IF(AC20="DTD","DP","Check PROJECT STAGE"))) -> Check PROJECT STAGE | AX20: =IF(AY20>"0","-","") | AY20: =IF(AO20=0,"",TEXT(AO20,"00")) | AZ20: =IF(BA20>"0","-","") | BA20: =IF(AQ20=0,"",TEXT(AQ20,"00")) | BC20: =IF(Y20="","Missing input data",IF(Y20="-","Missing input data",_xlfn.TEXTJOIN(,,A20:E20,AF20,AG20,P20,Y20,R20:S20,AP20,(TEXT(AQ20,"00")),AJ20,(TEXT(AK20,"v00")),AL20:AM20))) -> Missing input data | BD20: =IF(Y20="","Missing input data",IF(Y20="-","Missing input data",LEN(BC20))) -> Missing input data | BF20: =IF(AA20="","Missing input data",IF(AA20="-","Missing input data",_xlfn.TEXTJOIN(,,A20:E20,AF20,AG20,P20,AA20,R20:S20,AP20,(TEXT(AQ20,"00")),AJ20,(TEXT(AK20,"v00")),AL20:AM20))) -> Missing input data | BG20: =IF(AA20="","Missing input data",IF(AA20="-","Missing input data",LEN(BF20))) -> Missing input data | BI20: =IF(W20="","Missing input data",IF(W20="-","Missing input data",_xlfn.TEXTJOIN(,,A20:N20,Q20,T20,W20:Y20,AB20,AE20,AH20,(TEXT(AI20,"000000")),AL20:AM20))) -> Missing input data | BJ20: =IF(W20="","Missing input data",IF(W20="-","Missing input data",LEN(BI20))) -> Missing input data | BL20: =IF(W20="","Missing input data",IF(W20="-","Missing input data",_xlfn.TEXTJOIN(,,A20:N20,Q20,T20,W20:Y20,AB20,AE20,AH20,(TEXT(AI20,"000000")),AJ20,(TEXT(AK20,"000"))))) -> Missing input data | BM20: =IF(W20="","Missing input data",IF(W20="-","Missing input data",LEN(BL20))) -> Missing input data
B21: =IF(C21=0,"","-") | D21: =IF(E21=0,"","-") | F21: =IF(G21=0,"","_") | H21: =IF(I21=0,"","_") | J21: =IF(K21=0,"","-") | L21: =IF(M21=0,"","_") | N21: =IF(O21=0,"","_") | P21: =IF(Q21="","","-") | Q21: =IF(O21="","",VLOOKUP(O21,'DOCUMENT TYPE'!$A$2:$D$805,2,)) | R21: =IF(S21="","","-") | S21: =IF(O21="","",VLOOKUP(O21,'DOCUMENT TYPE'!$A$2:$D$805,3,)) | T21: =IF(U21=0,"","_") | V21: =IF(W21="","","-") | W21: =IF(U21="","",VLOOKUP(U21,'ACTIVITY & DISCIPLINE CODE'!$F$3:$I$1863,2,)) | X21: =IF(Y21="","","-") | Y21: =IF(U21="","",VLOOKUP(U21,'ACTIVITY & DISCIPLINE CODE'!$F$3:$I$1863,3,)) | Z21: =IF(AA21="","","_") | AA21: =IF(U21="","",VLOOKUP(U21,'ACTIVITY & DISCIPLINE CODE'!$F$3:$I$1863,4,)) | AB21: =IF(AC21=0,"","_") | AD21: =IF(AE21="","","-") | AE21: =IF(AC21="","",VLOOKUP(AC21,'PROJECT STAGE'!$A$2:$C$100,2,)) | AF21: =IF(AG21="","","_") | AG21: =IF(AC21="","",VLOOKUP(AC21,'PROJECT STAGE'!$A$2:$C$100,3,)) | AH21: =IF(AI21="","","_") | AJ21: =IF(AK21="","","_") | AL21: =IF(AM21="","","_") | AN21: =IF(AO21=0,"","_") | AP21: =IF(AQ21="","","-") | AS21: =IF(A21="RBDTD-LT", "RBDTDLT","Not LT section") -> Not LT section | AT21: =IF(AU21=0,"",".") -> . | AU21: =IF(O21=0,"No input data",INDEX('DOCUMENT TYPE'!D:D,MATCH(Filename!O21,'DOCUMENT TYPE'!A:A,0))) -> No input data | AV21: =IF(AW21=0,"","-") -> - | AW21: =IF(AC21="PD","PP",IF(AC21="MD","TP",IF(AC21="DTD","DP","Check PROJECT STAGE"))) -> Check PROJECT STAGE | AX21: =IF(AY21>"0","-","") | AY21: =IF(AO21=0,"",TEXT(AO21,"00")) | AZ21: =IF(BA21>"0","-","") | BA21: =IF(AQ21=0,"",TEXT(AQ21,"00")) | BC21: =IF(Y21="","Missing input data",IF(Y21="-","Missing input data",_xlfn.TEXTJOIN(,,A21:E21,AF21,AG21,P21,Y21,R21:S21,AP21,(TEXT(AQ21,"00")),AJ21,(TEXT(AK21,"v00")),AL21:AM21))) -> Missing input data | BD21: =IF(Y21="","Missing input data",IF(Y21="-","Missing input data",LEN(BC21))) -> Missing input data | BF21: =IF(AA21="","Missing input data",IF(AA21="-","Missing input data",_xlfn.TEXTJOIN(,,A21:E21,AF21,AG21,P21,AA21,R21:S21,AP21,(TEXT(AQ21,"00")),AJ21,(TEXT(AK21,"v00")),AL21:AM21))) -> Missing input data | BG21: =IF(AA21="","Missing input data",IF(AA21="-","Missing input data",LEN(BF21))) -> Missing input data | BI21: =IF(W21="","Missing input data",IF(W21="-","Missing input data",_xlfn.TEXTJOIN(,,A21:N21,Q21,T21,W21:Y21,AB21,AE21,AH21,(TEXT(AI21,"000000")),AL21:AM21))) -> Missing input data | BJ21: =IF(W21="","Missing input data",IF(W21="-","Missing input data",LEN(BI21))) -> Missing input data | BL21: =IF(W21="","Missing input data",IF(W21="-","Missing input data",_xlfn.TEXTJOIN(,,A21:N21,Q21,T21,W21:Y21,AB21,AE21,AH21,(TEXT(AI21,"000000")),AJ21,(TEXT(AK21,"000"))))) -> Missing input data | BM21: =IF(W21="","Missing input data",IF(W21="-","Missing input data",LEN(BL21))) -> Missing input data
B22: =IF(C22=0,"","-") | D22: =IF(E22=0,"","-") | F22: =IF(G22=0,"","_") | H22: =IF(I22=0,"","_") | J22: =IF(K22=0,"","-") | L22: =IF(M22=0,"","_") | N22: =IF(O22=0,"","_") | P22: =IF(Q22="","","-") | Q22: =IF(O22="","",VLOOKUP(O22,'DOCUMENT TYPE'!$A$2:$D$805,2,)) | R22: =IF(S22="","","-") | S22: =IF(O22="","",VLOOKUP(O22,'DOCUMENT TYPE'!$A$2:$D$805,3,)) | T22: =IF(U22=0,"","_") | V22: =IF(W22="","","-") | W22: =IF(U22="","",VLOOKUP(U22,'ACTIVITY & DISCIPLINE CODE'!$F$3:$I$1863,2,)) | X22: =IF(Y22="","","-") | Y22: =IF(U22="","",VLOOKUP(U22,'ACTIVITY & DISCIPLINE CODE'!$F$3:$I$1863,3,)) | Z22: =IF(AA22="","","_") | AA22: =IF(U22="","",VLOOKUP(U22,'ACTIVITY & DISCIPLINE CODE'!$F$3:$I$1863,4,)) | AB22: =IF(AC22=0,"","_") | AD22: =IF(AE22="","","-") | AE22: =IF(AC22="","",VLOOKUP(AC22,'PROJECT STAGE'!$A$2:$C$100,2,)) | AF22: =IF(AG22="","","_") | AG22: =IF(AC22="","",VLOOKUP(AC22,'PROJECT STAGE'!$A$2:$C$100,3,)) | AH22: =IF(AI22="","","_") | AJ22: =IF(AK22="","","_") | AL22: =IF(AM22="","","_") | AN22: =IF(AO22=0,"","_") | AP22: =IF(AQ22="","","-") | AS22: =IF(A22="RBDTD-LT", "RBDTDLT","Not LT section") -> Not LT section | AT22: =IF(AU22=0,"",".") -> . | AU22: =IF(O22=0,"No input data",INDEX('DOCUMENT TYPE'!D:D,MATCH(Filename!O22,'DOCUMENT TYPE'!A:A,0))) -> No input data | AV22: =IF(AW22=0,"","-") -> - | AW22: =IF(AC22="PD","PP",IF(AC22="MD","TP",IF(AC22="DTD","DP","Check PROJECT STAGE"))) -> Check PROJECT STAGE | AX22: =IF(AY22>"0","-","") | AY22: =IF(AO22=0,"",TEXT(AO22,"00")) | AZ22: =IF(BA22>"0","-","") | BA22: =IF(AQ22=0,"",TEXT(AQ22,"00")) | BC22: =IF(Y22="","Missing input data",IF(Y22="-","Missing input data",_xlfn.TEXTJOIN(,,A22:E22,AF22,AG22,P22,Y22,R22:S22,AP22,(TEXT(AQ22,"00")),AJ22,(TEXT(AK22,"v00")),AL22:AM22))) -> Missing input data | BD22: =IF(Y22="","Missing input data",IF(Y22="-","Missing input data",LEN(BC22))) -> Missing input data | BF22: =IF(AA22="","Missing input data",IF(AA22="-","Missing input data",_xlfn.TEXTJOIN(,,A22:E22,AF22,AG22,P22,AA22,R22:S22,AP22,(TEXT(AQ22,"00")),AJ22,(TEXT(AK22,"v00")),AL22:AM22))) -> Missing input data | BG22: =IF(AA22="","Missing input data",IF(AA22="-","Missing input data",LEN(BF22))) -> Missing input data | BI22: =IF(W22="","Missing input data",IF(W22="-","Missing input data",_xlfn.TEXTJOIN(,,A22:N22,Q22,T22,W22:Y22,AB22,AE22,AH22,(TEXT(AI22,"000000")),AL22:AM22))) -> Missing input data | BJ22: =IF(W22="","Missing input data",IF(W22="-","Missing input data",LEN(BI22))) -> Missing input data | BL22: =IF(W22="","Missing input data",IF(W22="-","Missing input data",_xlfn.TEXTJOIN(,,A22:N22,Q22,T22,W22:Y22,AB22,AE22,AH22,(TEXT(AI22,"000000")),AJ22,(TEXT(AK22,"000"))))) -> Missing input data | BM22: =IF(W22="","Missing input data",IF(W22="-","Missing input data",LEN(BL22))) -> Missing input data
... B1000: =IF(C1000=0,"","-") | D1000: =IF(E1000=0,"","-") | F1000: =IF(G1000=0,"","_") | H1000: =IF(I1000=0,"","_") | J1000: =IF(K1000=0,"","-") | L1000: =IF(M1000=0,"","_") | N1000: =IF(O1000=0,"","_") | P1000: =IF(Q1000="","","-") | Q1000: =IF(O1000="","",VLOOKUP(O1000,'DOCUMENT TYPE'!$A$2:$D$805,2,)) | R1000: =IF(S1000="","","-") | S1000: =IF(O1000="","",VLOOKUP(O1000,'DOCUMENT TYPE'!$A$2:$D$805,3,)) | T1000: =IF(U1000=0,"","_") | V1000: =IF(W1000="","","-") | W1000: =IF(U1000="","",VLOOKUP(U1000,'ACTIVITY & DISCIPLINE CODE'!$F$3:$I$1863,2,)) | X1000: =IF(Y1000="","","-") | Y1000: =IF(U1000="","",VLOOKUP(U1000,'ACTIVITY & DISCIPLINE CODE'!$F$3:$I$1863,3,)) | Z1000: =IF(AA1000="","","_") | AA1000: =IF(U1000="","",VLOOKUP(U1000,'ACTIVITY & DISCIPLINE CODE'!$F$3:$I$1863,4,)) | AB1000: =IF(AC1000=0,"","_") | AD1000: =IF(AE1000="","","-") | AE1000: =IF(AC1000="","",VLOOKUP(AC1000,'PROJECT STAGE'!$A$2:$C$100,2,)) | AF1000: =IF(AG1000="","","_") | AG1000: =IF(AC1000="","",VLOOKUP(AC1000,'PROJECT STAGE'!$A$2:$C$100,3,)) | AH1000: =IF(AI1000="","","_") | AJ1000: =IF(AK1000="","","_") | AL1000: =IF(AM1000="","","_") | AN1000: =IF(AO1000=0,"","_") | AP1000: =IF(AQ1000="","","-") | AS1000: =IF(A1000="RBDTD-LT", "RBDTDLT","Not LT section") -> Not LT section | AT1000: =IF(AU1000=0,"",".") -> . | AU1000: =IF(O1000=0,"No input data",INDEX('DOCUMENT TYPE'!D:D,MATCH(Filename!O1000,'DOCUMENT TYPE'!A:A,0))) -> No input data | AV1000: =IF(AW1000=0,"","-") -> - | AW1000: =IF(AC1000="PD","PP",IF(AC1000="MD","TP",IF(AC1000="DTD","DP","Check PROJECT STAGE"))) -> Check PROJECT STAGE | AX1000: =IF(AY1000>"0","-","") | AY1000: =IF(AO1000=0,"",TEXT(AO1000,"00")) | AZ1000: =IF(BA1000>"0","-","") | BA1000: =IF(AQ1000=0,"",TEXT(AQ1000,"00")) | BC1000: =IF(Y1000="","Missing input data",IF(Y1000="-","Missing input data",_xlfn.TEXTJOIN(,,A1000:E1000,AF1000,AG1000,P1000,Y1000,R1000:S1000,AP1000,(TEXT(AQ1000,"00")),AJ1000,(TEXT(AK1000,"v00")),AL1000:AM1000))) -> Missing input data | BD1000: =IF(Y1000="","Missing input data",IF(Y1000="-","Missing input data",LEN(BC1000))) -> Missing input data | BF1000: =IF(AA1000="","Missing input data",IF(AA1000="-","Missing input data",_xlfn.TEXTJOIN(,,A1000:E1000,AF1000,AG1000,P1000,AA1000,R1000:S1000,AP1000,(TEXT(AQ1000,"00")),AJ1000,(TEXT(AK1000,"v00")),AL1000:AM1000))) -> Missing input data | BG1000: =IF(AA1000="","Missing input data",IF(AA1000="-","Missing input data",LEN(BF1000))) -> Missing input data | BI1000: =IF(W1000="","Missing input data",IF(W1000="-","Missing input data",_xlfn.TEXTJOIN(,,A1000:N1000,Q1000,T1000,W1000:Y1000,AB1000,AE1000,AH1000,(TEXT(AI1000,"000000")),AL1000:AM1000))) -> Missing input data | BJ1000: =IF(W1000="","Missing input data",IF(W1000="-","Missing input data",LEN(BI1000))) -> Missing input data | BL1000: =IF(W1000="","Missing input data",IF(W1000="-","Missing input data",_xlfn.TEXTJOIN(,,A1000:N1000,Q1000,T1000,W1000:Y1000,AB1000,AE1000,AH1000,(TEXT(AI1000,"000000")),AJ1000,(TEXT(AK1000,"000"))))) -> Missing input data | BM1000: =IF(W1000="","Missing input data",IF(W1000="-","Missing input data",LEN(BL1000))) -> Missing input data
D1001: =IF(E1001=0,"","-")
D1002: =IF(E1002=0,"","-")
D1003: =IF(E1003=0,"","-")
D1004: =IF(E1004=0,"","-")
D1005: =IF(E1005=0,"","-")
D1006: =IF(E1006=0,"","-")
D1007: =IF(E1007=0,"","-")
D1008: =IF(E1008=0,"","-")
D1009: =IF(E1009=0,"","-")
D1010: =IF(E1010=0,"","-")
D1011: =IF(E1011=0,"","-")
D1012: =IF(E1012=0,"","-")
... D1292: =IF(E1292=0,"","-")

Sheet PROJECT ID
A1: CODE | B1: DESCTIPTION
A2: RBDTD-EE | B2: Design section in Estonia

Sheet SECTION ID
A1: CODE | B1: DESCTIPTION
A2: ZZ | B2: No section
A3: DS1 | B3: Design section No.1
A4: SS | B4: Signaling subsystem section
A5: ES | B5: Energy subsystem section
B6: To be continued if required. Any code and description shall be agreed with the Client.

Sheet SUB-SECTION ID
A1: CODE | B1: DESCTIPTION
A2: ZZ | B2: No sub-section
A3: DPS1 | B3: Design Priority section No.1
A4: DPS2 | B4: Design Priority section No.2
A5: DPS3 | B5: Design Priority section No.3
A6: DPS4 | B6: Design Priority section No.4
A7: DPS5 | B7: Design Priority section No.5
B8: To be continued if required. Any code and description shall be agreed with the Client.

Sheet ORIGINATOR_SUPPLIER
A1: CODE | B1: NAME
A2: AFR | B2: Afry
A3: ALL | B3: Allspark
A4: ARD | B4: Ardanuy
A5: ATE | B5: Atemo OÜ
A6: ENS | B6: Enersense AS
A7: GRK | B7: GRK infra AS
A8: HPT | B8: Hepta Group Energy OÜ
A9: INF | B9: INF INFRA OÜ
A10: KKP | B10: Keskkonnaprojekt AS
A11: KMG | B11: KMG Inseneriehituse AS
A12: KPR | B12: K-Projekt (ET)
... A31: YIT | B31: AS YIT Eesti
B32: To be continued if required. Any code and description shall be agreed with the Client.

Sheet VOLUME_SYSTEM
A1: IN FORCE CODE | B1: VE CODE | C1: MD CODE | D1: DTD | E1: RBR-Functional classification | F1: NAME / TYPE | G1: COUNTRY | H1: PD code | I1: PD Section | J1: Municipality | K1: WGS84 Long X Coordinate | L1: WGS84 Lat Y Coordinate | M1: Characteristics of Crossing / Road / Utility | N1: Affected party | O1: PD_km | P1: Type of data | Q1: Date | R1: Order | S1: Order with roads | T1: Archive | U1: New
A2: 000000 | B2: 000000 | C2: 000000 | F2: No Volume applicable | R2: 1 | S2: 1
A3: ZZZZZZ | B3: ZZZZZZ | C3: ZZZZZZ | F3: Multiple volumes applicable | R3: 2 | S3: 2
A4: OS1600 | B4: OS1600 | C4: OS1600 | E4: PP-FA-PTLO-00 | F4: Local Passenger Stop or Station | G4: EE | I4: 1 | K4: 59.179078 | L4: 24.770408 | M4: Kohila Local station | O4: 3+800 | P4: Facility/Station | R4: 3 | S4: 3
A5: OS160101 | C5: OS1601 | D5: OS160101 | E5: AR-BD-PLAT-TR | F5: Platform-Train Stn | G5: EE | I5: 1 | K5: 59.179182 | L5: 24.770511 | M5: Kohila Station Platform / Canopies and other structures on the platforms | O5: 3+800 | P5: Other | R5: 4 | S5: 4
A6: OS160102 | C6: OS1602 | D6: OS160102 | E6: AR-BD-PLAT-TR | F6: Platform-Train Stn | G6: EE | I6: 1 | K6: 59.179102 | L6: 24.770335 | M6: Kohila Station platform right | O6: 3+800 | P6: Other | R6: 5 | S6: 5
A7: OS160104 | D7: OS160104 | E7: CV-RO-ROAD-CA | F7: Road-Corridor Access | G7: EE | I7: 1 | K7: 59.180025 | L7: 24.769897 | M7: Evacuation path platform 1 | O7: 3+800 | P7: Road | R7: 6 | S7: 6 | T7: x
A8: OR160104 | D8: OR160104 | E8: CV-RO-ROAD-CA | F8: Road-Corridor Access | G8: EE | I8: 1 | K8: 59.180025 | L8: 24.769897 | M8: Evacuation path platform 1 | O8: 3+800 | P8: Road | Q8: 20.10.2025 | R8: 7 | S8: 7 | U8: new
A9: OS160105 | D9: OS160105 | E9: CV-RO-ROAD-CA | F9: Road-Corridor Access | G9: EE | I9: 1 | K9: 59.178213 | L9: 24.771468 | M9: Evacuation path platform 1 | O9: 3+800 | P9: Road | R9: 8 | S9: 8 | T9: x
A10: OR160105 | D10: OR160105 | E10: CV-RO-ROAD-CA | F10: Road-Corridor Access | G10: EE | I10: 1 | K10: 59.178213 | L10: 24.771468 | M10: Evacuation path platform 1 | O10: 3+800 | P10: Road | Q10: 20.10.2025 | R10: 9 | S10: 9 | U10: new
A11: OS160106 | D11: OS160106 | E11: CV-RO-ROAD-CA | F11: Road-Corridor Access | G11: EE | I11: 1 | K11: 59.179941 | L11: 24.769465 | M11: Evacuation path platform 2 | O11: 3+800 | P11: Road | R11: 10 | S11: 10 | T11: x
A12: OR160106 | D12: OR160106 | E12: CV-RO-ROAD-CA | F12: Road-Corridor Access | G12: EE | I12: 1 | K12: 59.179941 | L12: 24.769465 | M12: Evacuation path platform 2 | O12: 3+800 | P12: Road | Q12: 20.10.2025 | R12: 11 | S12: 11 | U12: new
A13: OS160107 | D13: OS160107 | E13: CV-RO-ROAD-CA | F13: Road-Corridor Access | G13: EE | I13: 1 | K13: 59.178128 | L13: 24.770966 | M13: Evacuation path platform 2 | O13: 3+800 | P13: Road | R13: 12 | S13: 12 | T13: x
A14: OR160107 | D14: OR160107 | E14: CV-RO-ROAD-CA | F14: Road-Corridor Access | G14: EE | I14: 1 | K14: 59.178128 | L14: 24.770966 | M14: Evacuation path platform 2 | O14: 3+800 | P14: Road | Q14: 20.10.2025 | R14: 13 | S14: 13 | U14: new
A15: OS160121 | C15: OS160121 | E15: CV-MS-INTF-EL | F15: Electricity Interface | G15: EE | I15: 1 | K15: 59.179077 | L15: 24.770409 | M15: Kohila Station Platform / Electricity, external( High-voltage) | O15: 3+800 | P15: Interface | R15: 14 | S15: 14
A16: OS160122 | C16: OS160122 | E16: CV-MS-INTF-00 | F16: Unidentified interface | G16: EE | I16: 1 | K16: 59.179077 | L16: 24.770409 | M16: Kohila Station Platform / Water and sewerage, external | O16: 3+800 | P16: Interface | R16: 15 | S16: 15
A17: OS160123 | D17: OS160123 | E17: CV-MS-INTF-EL | F17: Electricity Interface | G17: EE | I17: 1 | K17: 59.179224 | L17: 24.770614 | M17: Kohila Station Low-voltage( platforms and overpass)(low voltage) | O17: 3+800 | P17: Interface | R17: 16 | S17: 16
A18: OS160301 | C18: OS1603 | D18: OS160301 | E18: AR-BD-BLDG-SN | F18: Station Building | G18: EE | I18: 1 | K18: 59.179077 | L18: 24.770409 | M18: Kohila Local Station / Station Building (including utilities, art) excl. structural engineering design below platforms floor surface. Excl. canopies and other structures on the platforms | O18: 3+800 | P18: Other | R18: 17 | S18: 17 | T18: x
A19: OS1604 | C19: OS1604 | E19: AR-BD-BLDG-SN | F19: Station Building | G19: EE | I19: 1 | K19: 59.179077 | L19: 24.770409 | M19: 426 | O19: 3+800 | P19: Other | R19: 18 | S19: 18 | T19: x
A20: OS160401 | C20: OS160401 | E20: AR-BD-BLDG-SN | F20: Station Building | G20: EE | I20: 1 | K20: 59.179077 | L20: 24.770408 | M20: Kohila Local Station / Bus stop. Bike parking. Debris station. | O20: 3+800 | P20: Other | R20: 19 | S20: 19 | T20: x
A21: OS160402 | C21: OS160402 | E21: CV-BR-UPSS-RD | F21: Underpass-Road | G21: EE | I21: 1 | K21: 59.179077 | L21: 24.770409 | M21: Kohila Local Station / Structural Engineering design below platforms floor surface | O21: 3+800 | P21: Underpass | R21: 20 | S21: 20 | T21: x
A22: OS160403 | C22: OS160403 | E22: CV-BR-OPSS-PD | F22: Overpass-Pedestrian | G22: EE | I22: 1 | K22: 59.179077 | L22: 24.770409 | M22: Overpass Kohila Pedestrian crossing. Stairs from platform floor | O22: 3+800 | P22: Overpass | R22: 21 | S22: 21
A23: OS160411 | C23: OS160411 | E23: AR-UD-LSCP-00 | F23: Landscaping | G23: EE | I23: 1 | K23: 59.179077 | L23: 24.770409 | M23: Kohila Local Station infrastucture / Urban design | O23: 3+800 | P23: Other | R23: 22 | S23: 22 | T23: x
A24: OS160412 | C24: OS160412 | E24: CV-RO-ROAD-00 | F24: Road-Not specified | G24: EE | I24: 1 | K24: 59.179077 | L24: 24.770409 | M24: Kohila Local Station infrastucture / Outdoor area+ parking | O24: 3+800 | P24: Road | R24: 23 | S24: 23 | T24: x
A25: OS160413 | D25: OS160413 | E25: CV-RO-ROAD-SQ | F25: Square | G25: EE | I25: 1 | K25: 59.178787 | L25: 24.769951 | M25: Kohila outdoor area subsoil work | O25: 3+850 | P25: Road | Q25: 20.10.2025 | R25: 24 | S25: 24 | U25: new
A26: OS160421 | C26: OS160421 | E26: CV-MS-INTF-EL | F26: Electricity Interface | G26: EE | I26: 1 | K26: 59.179077 | L26: 24.770409 | M26: Kohila Local Station infrastucture / Electricity, external | O26: 3+800 | P26: Interface | R26: 25 | S26: 25 | T26: x
A27: OS160422 | C27: OS160422 | E27: CV-MS-INTF-EL | F27: Electricity Interface | G27: EE | I27: 1 | K27: 59.179077 | L27: 24.770409 | M27: Overpass Kohila. Pedestrian crossing / Electricity, external | O27: 3+800 | P27: Interface | R27: 26 | S27: 26 | T27: x
A28: OS160423 | C28: OS160423 | E28: CV-MS-INTF-00 | F28: Unidentified interface | G28: EE | I28: 1 | K28: 59.179077 | L28: 24.770409 | M28: Kohila Local Station infrastucture / Water and sewerage, external | O28: 3+800 | P28: Interface | R28: 27 | S28: 27 | T28: x
A29: OS160424 | C29: OS160424 | E29: CV-MS-INTF-00 | F29: Unidentified interface | G29: EE | I29: 1 | K29: 59.179077 | L29: 24.770409 | M29: Overpass Kohila. Pedestrian crossing / Water and sewerage, external | O29: 3+800 | P29: Interface | R29: 28 | S29: 28 | T29: x
A30: OS160425 | D30: OS160425 | E30: CV-MS-INTF-EL | F30: Electricity Interface | G30: EE | I30: 1 | K30: 59.178964 | L30: 24.769241 | M30: Kohila station Street lighting+electricity( Outdoor) | O30: 3+800 | P30: Interface | R30: 29 | S30: 29 | T30: x
A31: OS160426 | D31: OS160426 | E31: CV-MS-INTF-RW | F31: Temorary rainwater drainage pipeline | G31: EE | I31: 1 | K31: 59.178803 | L31: 24.769242 | M31: Kohila station temporary drainage of rainwater through an outdoor | O31: 3+800 | P31: Other | Q31: 13.05.2025 | R31: 30 | S31: 30
A32: RW1000 | C32: RW1000 | E32: TR-TR-TRAK-ML | F32: Track-Mainline | G32: EE | H32: ZZZZ | I32: 1 | K32: 59.173504 | L32: 24.774533 | M32: Railway Kohila | O32: 0+000 - 9+416 | P32: Track | R32: 31 | S32: 31
A33: RW100100 | C33: RW1000 | D33: RW100100 | E33: TR-TR-SUBS-00 | F33: Substructure | G33: EE | H33: ZZZZ | I33: 1 | K33: 59.171976 | L33: 24.783121 | M33: Railway Kohila substructure/Railway main line drainage | O33: 0+000 - 9+416 | P33: Substructure | R33: 32 | S33: 32
A34: RW100200 | C34: RW1000 | D34: RW100200 | E34: TR-TR-SUPS-00 | F34: Superstructure | G34: EE | H34: ZZZZ | I34: 1 | K34: 59.173033 | L34: 24.782909 | M34: Railway Kohila | O34: 0+000 - 9+416 | P34: Superstructure | R34: 33 | S34: 33
A35: RW100300 | C35: RW1000 | D35: RW100300 | E35: CV-MS-INTF-SG | F35: Signalling Interface | G35: EE | H35: ZZZZ | I35: 1 | K35: 59.172508 | L35: 24.782903 | M35: RW1300 CCS Cable channel | O35: 0+000 - 9+416 | P35: Interface | R35: 34 | S35: 34
A36: RW100600 | C36: RW1000 | D36: RW100600 | E36: CV-FN-FENC-00 | F36: Fence | G36: EE | H36: ZZZZ | I36: 1 | K36: 59.17234727 | L36: 24.776375137 | M36: Railway Kohila fences | O36: 0+000 - 9+416 | P36: Fence | R36: 35 | S36: 35
A37: RW100800 | C37: RW1000 | D37: RW100800 | E37: AR-UD-LSCP-00 | F37: Landscaping | G37: EE | I37: 1 | K37: 59.17296 | L37: 24.775718 | M37: Railway landscaping | O37: 0+000 - 9+416 | P37: Other | Q37: 08.05.2025 | R37: 36 | S37: 36
A38: OR1000 | D38: OR1000 | E38: CV-RO-ROAD-CM | F38: Road-Maintenance | G38: EE | H38: ZZZZ | I38: 1 | K38: 59.174 | L38: 24.783 | M38: Railway maintenance roads | O38: 0+000 - 9+416 | P38: Road | R38: 37 | S38: 37
A39: BR1210 | C39: BR1210 | E39: CV-BR-OPSS-RD | F39: Overpass-Road | G39: EE | H39: 07-BR10 | I39: 1 | K39: 59.200531 | L39: 24.752122 | M39: Tagadi road nr 3170198 | O39: 1+192 | P39: Overpass | R39: 38 | S39: 38
A40: OR1208 | C40: OR1208 | E40: CV-RO-ROAD-LO | F40: Road-Local | G40: EE | I40: 1 | K40: 59.199467 | L40: 24.752553 | M40: Kurtna road nr 3170009 | N40: BR1210 | O40: 1+192 | P40: Road | R40: 39 | S40: 39
...

Sheet ZONE
A1: CODE | B1: NAME
A2: ZZ | B2: Whole Zone
A3: 00 | B3: No Zone applicable
A4: SB | B4: Substructure | C4: Not in use
A5: SP | B5: Superstructure | C5: Not in use
A6: EN | B6: Entrances | C6: Not in use
A7: AG | B7: Above Ground | C7: Not in use
B8: To be continued if required. Any code and description shall be agreed with the Client.

Sheet LOCATION
A1: CODE | B1: CHAINAGE KM
A2: 0000 | B2: No location applicable
A3: ZZZZ | B3: Multiple Locations applicable | F3: NOTES:
A4: 0001 | B4: 0 | C4: - | D4: =B5 -> 1000 | F4: Chainage and codes are relative for each desing priority section (DPS) starting from 0+000
A5: 0002 | B5: =B4+1000 -> 1000 | C5: =C4 -> - | D5: =B6 -> 2000 | F5: Absolute chainage shall be introduced after all design sections are finalized in MD stage
A6: 0003 | B6: =B5+1000 -> 2000 | C6: =C5 -> - | D6: =B7 -> 3000
A7: 0004 | B7: =B6+1000 -> 3000 | C7: =C6 -> - | D7: =B8 -> 4000
A8: 0005 | B8: =B7+1000 -> 4000 | C8: =C7 -> - | D8: =B9 -> 5000
A9: 0006 | B9: =B8+1000 -> 5000 | C9: =C8 -> - | D9: =B10 -> 6000
A10: 0007 | B10: =B9+1000 -> 6000 | C10: =C9 -> - | D10: =B11 -> 7000
A11: 0008 | B11: =B10+1000 -> 7000 | C11: =C10 -> - | D11: =B12 -> 8000
A12: 0009 | B12: =B11+1000 -> 8000 | C12: =C11 -> - | D12: =B13 -> 9000
A13: 0010 | B13: =B12+1000 -> 9000 | C13: =C12 -> - | D13: =B14 -> 10000
A14: 0011 | B14: =B13+1000 -> 10000 | C14: =C13 -> - | D14: =B15 -> 11000
A15: 0012 | B15: =B14+1000 -> 11000 | C15: =C14 -> - | D15: =B16 -> 12000
A16: 0013 | B16: =B15+1000 -> 12000 | C16: =C15 -> - | D16: =B17 -> 13000
A17: 0014 | B17: =B16+1000 -> 13000 | C17: =C16 -> - | D17: =B18 -> 14000
... A22: 0019 | B22: =B21+1000 -> 18000 | C22: =C21 -> - | D22: =B23 -> 19000
A23: 0020 | B23: =B22+1000 -> 19000 | C23: =C22 -> -
B24: To be continued if required. Any code and description shall be agreed with the Client.

Sheet ACTIVITY & DISCIPLINE CODE
B1: Folder number | C1: Activity/Discipline code description | D1: Volsys. Code | E1: Folder number | F1: Activity/Discipline description RBR | G1: Activity/Discipline code | J1: Activity/Discipline description EHR | K1: Activity/Discipline description MNT | L1: Rev date | M1: Rev by
G2: RBR | H2: EHR | I2: MNT
A3: Overall (0-OV) | B3: 000 | C3: Model | E3: 01 | F3: landXML | G3: MO | H3: AA | I3: -
E4: 02 | F4: IFC | G4: MO | H4: AA | I4: -
E5: 03 | F5: RVT | G5: MO | H5: AA | I5: -
E6: 04 | F6: NWD | G6: MO | H6: AA | I6: -
E7: ... | F7: ... | G7: MO | H7: AA | I7: -
B8: 001 | C8: Minutes of Meeting | F8: Minutes of Meeting | G8: MOM | H8: AA | I8: -
