Workbook
Name Roles: #REF!

Sheet Filename
A2: RB file name content | K2: Only for EHR file name content!!! | X2: RB file name content | AN2: Only EHR file name content
A3: Project name | B3: - | C3: Originator/ Supplier/ Contractor | D3: - | E3: Volume_ System | F3: - | G3: Level-System | J3: _ | K3: Project stage | P3: - | Q3: Discipline code | X3: - | Y3: Document type | AD3: - | AE3: Discipline | AH3: - | AI3: Number | AJ3: _ | AK3: Revision No. | AL3: - | AM3: Drawing name/description | AN3: - | AO3: Document's running number within the project
Q4: Only for EHR file name
A5: PROJECT ID | C5: Abbreviation of the originator of the document Predefined list ORIGINATOR_SUPPLIER Provided by RB Rail AS | E5: VOLUME/ SYSTEM | G5: LEVEL-SYSTEM | I5: CODE | K5: Stage Description | M5: Stage Code RBR | O5: Stage Code EE | Q5: RBR discipline | S5: RBR CODE | U5: LOCAL CODE EHR | W5: LOCAL CODE MNT | Y5: Abbreviation of the document type. Predefined list DOCUMENT TYPE Provided by RB Rail AS | AA5: RBR document type | AC5: EE document type | AE5: Discipline Description | AG5: Discipline Code RBR | AI5: Unique ID number of each construction object 00001-99999 | AK5: Revision number 1-999 | AM5: Drawing name/description | AO5: Document's running number within the project According to LST 1516:2015
A6: Project name according to DTD TS Predefined list PROJECT ID Provided by RB Rail AS | E6: Code of the volume/ system. Predefined list VOLUME_SYSTEM Provided by RB Rail AS | G6: Code of the level or system. Predefined list LEVEL/SYSTEM Provided by RB Rail AS | I6: Code of the level or system. Predefined list LEVEL/SYSTEM Provided by RB Rail AS | K6: Abbreviation of the project stage. Predefined list PROJECT STAGE Provided by RB Rail AS | M6: Abbreviation of the project stage. Predefined list PROJECT STAGE Provided by RB Rail AS | O6: Abbreviation of the project stage. Predefined list PROJECT STAGE Provided by RB Rail AS | Q6: RBR discipline Predefined list Provided by RB Rail AS | S6: RBR discipline code Predefined list Provided by RB Rail AS | U6: Discipline code according to local legislation Predefined list | W6: Discipline code according to local legislation Predefined list | AA6: RBR document type code Predefined list Provided by RB Rail AS | AC6: EE document type code Predefined list Provided by RB Rail AS | AE6: Abbreviation of the project stage. Predefined list DISCIPLINE Provided by RB Rail AS | AG6: Abbreviation of the project stage. Predefined list DISCIPLINE Provided by RB Rail AS
AQ8: EE EHR file name | AR8: Length of filename, charecters | AT8: RB Design Document file number | AU8: Length of filename, charecters
A9: EE2100 | B9: =IF(C9=0,"","-") -> - | C9: SWE | D9: =IF(E9=0,"","-") -> - | E9: ZZZZZZ | F9: =IF(G9=0,"","-") -> - | G9: INFRA (Track and Civil Works) | H9: =IF(G9="","","-") -> - | I9: =IF(G9="","",VLOOKUP(G9,'LEVEL-SYSTEM'!$A$2:$B$849,2,)) -> IF | J9: =IF(K9=0,"","_") -> _ | K9: Preliminary design | L9: =IF(M9="","","-") -> - | M9: =IF(K9="","",VLOOKUP(K9,'PROJECT STAGE'!$A$2:$C$100,2,)) -> PD | N9: =IF(O9="","","-") -> - | O9: =IF(K9="","",VLOOKUP(K9,'PROJECT STAGE'!$A$2:$C$100,3,)) -> EP | P9: =IF(K9=0,"","-") -> - | Q9: Water Supply and Sewerage, external | R9: =IF(S9="","","-") -> - | S9: =IF(Q9="","",VLOOKUP(Q9,'ACTIVITY & DISCIPLINE CODE'!$F$3:$I$1890,2,)) -> WE | T9: =IF(U9="","","-") -> - | U9: =IF(Q9="","",VLOOKUP(Q9,'ACTIVITY & DISCIPLINE CODE'!$F$3:$I$1890,3,)) -> VKV | V9: =IF(W9="","","-") -> - | W9: =IF(Q9="","",VLOOKUP(Q9,'[1]ACTIVITY & DISCIPLINE CODE'!$F$3:$I$1862,4,)) -> TV | X9: =IF(U9="","","-") -> - | Y9: Model Document | Z9: =IF(AA9="","","-") -> - | AA9: =IF(Y9="","",VLOOKUP(Y9,'DOCUMENT TYPE'!$A$2:$C$837,2,)) -> MDL | AB9: =IF(AC9="","","-") -> - | AC9: =IF(Y9="","",VLOOKUP(Y9,'DOCUMENT TYPE'!$A$2:$C$837,3,)) -> 9 | AD9: =IF(AE9=0,"","-") -> - | AE9: Non-disciplinary / General Part | AF9: =IF(AG9="","","-") -> - | AG9: =IF(AE9="","",VLOOKUP(AE9,DISCIPLINE!$A$2:$C$845,2,)) -> X | AH9: =IF(AI9="","","-") -> - | AI9: 1 | AJ9: =IF(AI9="","","_") -> _ | AK9: 9 | AL9: =IF(AM9="","","-") -> - | AM9: BIMExecutionPlan | AN9: =IF(AM9="","","-") -> - | AO9: 2 | AQ9: =IF(U9="","Missing input data",IF(U9="-","Missing input data",_xlfn.TEXTJOIN(,,A9,E9,J9,O9,T9:U9,AB9:AC9,AN9,(TEXT(AO9,"00")),AJ9,(TEXT(AK9,"v00")),"_",AM9))) -> EE2100ZZZZZZ_EP-VKV-9-02_v09_BIMExecutionPlan | AR9: =IF(AC9="","Missing input data",IF(AC9="-","Missing input data",LEN(AQ9))) -> 45 | AT9: =IF(I9="","Missing input data",IF(I9="-","Missing input data",_xlfn.TEXTJOIN(,,A9:E9,H9:I9,Z9:AA9,AD9,AG9,AH9,(TEXT(AI9,"00000")),AJ9,AM9))) -> EE2100-SWE-ZZZZZZ-IF-MDL-X-00001_BIMExecutionPlan | AU9: =IF(I9="","Missing input data",IF(I9="-","Missing input data",LEN(AT9))) -> 49
A10: RBEE | B10: =IF(C10=0,"","-") -> - | C10: GRK | D10: =IF(E10=0,"","-") -> - | E10: ZZZZZZ | F10: =IF(G10=0,"","-") -> - | G10: Multiple Levels | H10: =IF(G10="","","-") -> - | I10: =IF(G10="","",VLOOKUP(G10,'LEVEL-SYSTEM'!$A$2:$B$849,2,)) -> ZZ | J10: =IF(K10=0,"","_") | L10: =IF(M10="","","-") | M10: =IF(K10="","",VLOOKUP(K10,DISCIPLINE!$A$2:$C$845,2,)) | N10: =IF(O10="","","-") | O10: =IF(M10="","",VLOOKUP(M10,DISCIPLINE!$A$2:$C$845,2,)) | P10: =IF(K10=0,"","-") | R10: =IF(S10="","","-") | S10: =IF(Q10="","",VLOOKUP(Q10,'[1]ACTIVITY & DISCIPLINE CODE'!$F$3:$I$1862,2,)) | T10: =IF(U10="","","-") | U10: =IF(Q10="","",VLOOKUP(Q10,'[1]ACTIVITY & DISCIPLINE CODE'!$F$3:$I$1862,3,)) | V10: =IF(W10="","","-") | W10: =IF(Q10="","",VLOOKUP(Q10,'[2]ACTIVITY & DISCIPLINE CODE'!$F$3:$I$1850,4,)) | X10: =IF(U10="","","-") | Y10: Template | Z10: =IF(AA10="","","-") -> - | AA10: =IF(Y10="","",VLOOKUP(Y10,'DOCUMENT TYPE'!$A$7:$C$837,2,)) -> TPL | AB10: =IF(AC10="","","-") -> - | AC10: =IF(Y10="","",VLOOKUP(Y10,'DOCUMENT TYPE'!$A$7:$C$837,3,)) -> 1 | AD10: =IF(AE10=0,"","-") -> - | AE10: Non-disciplinary / General Part | AF10: =IF(AG10="","","-") -> - | AG10: =IF(AE10="","",VLOOKUP(AE10,DISCIPLINE!$A$2:$C$845,2,)) -> X | AH10: =IF(AI10="","","-") -> - | AI10: 1 | AJ10: =IF(AI10="","","_") -> _ | AK10: 1 | AL10: =IF(AM10="","","-") -> - | AM10: Test 123 | AN10: =IF(AM10="","","-") -> - | AQ10: =IF(U10="","Missing input data",IF(U10="-","Missing input data",_xlfn.TEXTJOIN(,,A10,E10,J10,O10,T10:U10,AB10:AC10,AN10,(TEXT(AO10,"00")),AJ10,(TEXT(AK10,"v00")),"_",AM10))) -> Missing input data | AR10: =IF(AC10="","Missing input data",IF(AC10="-","Missing input data",LEN(AQ10))) -> 18 | AT10: =IF(I10="","Missing input data",IF(I10="-","Missing input data",_xlfn.TEXTJOIN(,,A10:E10,H10:I10,Z10:AA10,AD10,AG10,AH10,(TEXT(AI10,"00000")),AJ10,AM10))) -> RBEE-GRK-ZZZZZZ-ZZ-TPL-X-00001_Test 123 | AU10: =IF(I10="","Missing input data",IF(I10="-","Missing input data",LEN(AT10))) -> 39
B11: =IF(C11=0,"","-") | D11: =IF(E11=0,"","-") -> - | E11: RW020100 | F11: =IF(G11=0,"","-") | H11: =IF(G11="","","-") | I11: =IF(G11="","",VLOOKUP(G11,'LEVEL-SYSTEM'!$A$2:$B$849,2,)) | J11: =IF(K11=0,"","_") | L11: =IF(M11="","","-") | M11: =IF(K11="","",VLOOKUP(K11,DISCIPLINE!$A$2:$C$845,2,)) | N11: =IF(O11="","","-") | O11: =IF(M11="","",VLOOKUP(M11,DISCIPLINE!$A$2:$C$845,2,)) | P11: =IF(K11=0,"","-") | R11: =IF(S11="","","-") | S11: =IF(Q11="","",VLOOKUP(Q11,'[1]ACTIVITY & DISCIPLINE CODE'!$F$3:$I$1862,2,)) | T11: =IF(U11="","","-") | U11: =IF(Q11="","",VLOOKUP(Q11,'[1]ACTIVITY & DISCIPLINE CODE'!$F$3:$I$1862,3,)) | V11: =IF(W11="","","-") | W11: =IF(Q11="","",VLOOKUP(Q11,'[2]ACTIVITY & DISCIPLINE CODE'!$F$3:$I$1850,4,)) | X11: =IF(U11="","","-") | Z11: =IF(AA11="","","-") | AA11: =IF(Y11="","",VLOOKUP(Y11,'DOCUMENT TYPE'!$A$7:$C$837,2,)) | AB11: =IF(AC11="","","-") | AC11: =IF(Y11="","",VLOOKUP(Y11,'DOCUMENT TYPE'!$A$7:$C$837,3,)) | AD11: =IF(AE11=0,"","-") | AF11: =IF(AG11="","","-") | AG11: =IF(AE11="","",VLOOKUP(AE11,DISCIPLINE!$A$2:$C$845,2,)) | AH11: =IF(AI11="","","-") | AJ11: =IF(AI11="","","_") | AL11: =IF(AM11="","","-") | AN11: =IF(AM11="","","-") | AQ11: =IF(U11="","Missing input data",IF(U11="-","Missing input data",_xlfn.TEXTJOIN(,,A11,E11,J11,O11,T11:U11,AB11:AC11,AN11,(TEXT(AO11,"00")),AJ11,(TEXT(AK11,"v00")),"_",AM11))) -> Missing input data | AR11: =IF(AC11="","Missing input data",IF(AC11="-","Missing input data",LEN(AQ11))) -> Missing input data | AT11: =IF(I11="","Missing input data",IF(I11="-","Missing input data",_xlfn.TEXTJOIN(,,A11:E11,H11:I11,Z11:AA11,AD11,AG11,AH11,(TEXT(AI11,"00000")),AJ11,AM11))) -> Missing input data | AU11: =IF(I11="","Missing input data",IF(I11="-","Missing input data",LEN(AT11))) -> Missing input data
B12: =IF(C12=0,"","-") | D12: =IF(E12=0,"","-") | F12: =IF(G12=0,"","-") | H12: =IF(G12="","","-") | I12: =IF(G12="","",VLOOKUP(G12,'LEVEL-SYSTEM'!$A$2:$B$849,2,)) | J12: =IF(K12=0,"","_") | L12: =IF(M12="","","-") | M12: =IF(K12="","",VLOOKUP(K12,DISCIPLINE!$A$2:$C$845,2,)) | N12: =IF(O12="","","-") | O12: =IF(M12="","",VLOOKUP(M12,DISCIPLINE!$A$2:$C$845,2,)) | P12: =IF(K12=0,"","-") | R12: =IF(S12="","","-") | S12: =IF(Q12="","",VLOOKUP(Q12,'[1]ACTIVITY & DISCIPLINE CODE'!$F$3:$I$1862,2,)) | T12: =IF(U12="","","-") | U12: =IF(Q12="","",VLOOKUP(Q12,'[1]ACTIVITY & DISCIPLINE CODE'!$F$3:$I$1862,3,)) | V12: =IF(W12="","","-") | W12: =IF(Q12="","",VLOOKUP(Q12,'[2]ACTIVITY & DISCIPLINE CODE'!$F$3:$I$1850,4,)) | X12: =IF(U12="","","-") | Z12: =IF(AA12="","","-") | AA12: =IF(Y12="","",VLOOKUP(Y12,'DOCUMENT TYPE'!$A$7:$C$837,2,)) | AB12: =IF(AC12="","","-") | AC12: =IF(Y12="","",VLOOKUP(Y12,'DOCUMENT TYPE'!$A$7:$C$837,3,)) | AD12: =IF(AE12=0,"","-") | AF12: =IF(AG12="","","-") | AG12: =IF(AE12="","",VLOOKUP(AE12,DISCIPLINE!$A$2:$C$845,2,)) | AH12: =IF(AI12="","","-") | AJ12: =IF(AI12="","","_") | AL12: =IF(AM12="","","-") | AN12: =IF(AM12="","","-") | AQ12: =IF(U12="","Missing input data",IF(U12="-","Missing input data",_xlfn.TEXTJOIN(,,A12,E12,J12,O12,T12:U12,AB12:AC12,AN12,(TEXT(AO12,"00")),AJ12,(TEXT(AK12,"v00")),"_",AM12))) -> Missing input data | AR12: =IF(AC12="","Missing input data",IF(AC12="-","Missing input data",LEN(AQ12))) -> Missing input data | AT12: =IF(I12="","Missing input data",IF(I12="-","Missing input data",_xlfn.TEXTJOIN(,,A12:E12,H12:I12,Z12:AA12,AD12,AG12,AH12,(TEXT(AI12,"00000")),AJ12,AM12))) -> Missing input data | AU12: =IF(I12="","Missing input data",IF(I12="-","Missing input data",LEN(AT12))) -> Missing input data
B13: =IF(C13=0,"","-") | D13: =IF(E13=0,"","-") | F13: =IF(G13=0,"","-") | H13: =IF(G13="","","-") | I13: =IF(G13="","",VLOOKUP(G13,'LEVEL-SYSTEM'!$A$2:$B$849,2,)) | J13: =IF(K13=0,"","_") | L13: =IF(M13="","","-") | M13: =IF(K13="","",VLOOKUP(K13,DISCIPLINE!$A$2:$C$845,2,)) | N13: =IF(O13="","","-") | O13: =IF(M13="","",VLOOKUP(M13,DISCIPLINE!$A$2:$C$845,2,)) | P13: =IF(K13=0,"","-") | R13: =IF(S13="","","-") | S13: =IF(Q13="","",VLOOKUP(Q13,'[1]ACTIVITY & DISCIPLINE CODE'!$F$3:$I$1862,2,)) | T13: =IF(U13="","","-") | U13: =IF(Q13="","",VLOOKUP(Q13,'[1]ACTIVITY & DISCIPLINE CODE'!$F$3:$I$1862,3,)) | V13: =IF(W13="","","-") | W13: =IF(Q13="","",VLOOKUP(Q13,'[2]ACTIVITY & DISCIPLINE CODE'!$F$3:$I$1850,4,)) | X13: =IF(U13="","","-") | Z13: =IF(AA13="","","-") | AA13: =IF(Y13="","",VLOOKUP(Y13,'DOCUMENT TYPE'!$A$7:$C$837,2,)) | AB13: =IF(AC13="","","-") | AC13: =IF(Y13="","",VLOOKUP(Y13,'DOCUMENT TYPE'!$A$7:$C$837,3,)) | AD13: =IF(AE13=0,"","-") | AF13: =IF(AG13="","","-") | AG13: =IF(AE13="","",VLOOKUP(AE13,DISCIPLINE!$A$2:$C$845,2,)) | AH13: =IF(AI13="","","-") | AJ13: =IF(AI13="","","_") | AL13: =IF(AM13="","","-") | AN13: =IF(AM13="","","-") | AQ13: =IF(U13="","Missing input data",IF(U13="-","Missing input data",_xlfn.TEXTJOIN(,,A13,E13,J13,O13,T13:U13,AB13:AC13,AN13,(TEXT(AO13,"00")),AJ13,(TEXT(AK13,"v00")),"_",AM13))) -> Missing input data | AR13: =IF(AC13="","Missing input data",IF(AC13="-","Missing input data",LEN(AQ13))) -> Missing input data | AT13: =IF(I13="","Missing input data",IF(I13="-","Missing input data",_xlfn.TEXTJOIN(,,A13:E13,H13:I13,Z13:AA13,AD13,AG13,AH13,(TEXT(AI13,"00000")),AJ13,AM13))) -> Missing input data | AU13: =IF(I13="","Missing input data",IF(I13="-","Missing input data",LEN(AT13))) -> Missing input data
B14: =IF(C14=0,"","-") | D14: =IF(E14=0,"","-") | F14: =IF(G14=0,"","-") | H14: =IF(G14="","","-") | I14: =IF(G14="","",VLOOKUP(G14,'LEVEL-SYSTEM'!$A$2:$B$849,2,)) | J14: =IF(K14=0,"","_") | L14: =IF(M14="","","-") | M14: =IF(K14="","",VLOOKUP(K14,DISCIPLINE!$A$2:$C$845,2,)) | N14: =IF(O14="","","-") | O14: =IF(M14="","",VLOOKUP(M14,DISCIPLINE!$A$2:$C$845,2,)) | P14: =IF(K14=0,"","-") | R14: =IF(S14="","","-") | S14: =IF(Q14="","",VLOOKUP(Q14,'[1]ACTIVITY & DISCIPLINE CODE'!$F$3:$I$1862,2,)) | T14: =IF(U14="","","-") | U14: =IF(Q14="","",VLOOKUP(Q14,'[1]ACTIVITY & DISCIPLINE CODE'!$F$3:$I$1862,3,)) | V14: =IF(W14="","","-") | W14: =IF(Q14="","",VLOOKUP(Q14,'[2]ACTIVITY & DISCIPLINE CODE'!$F$3:$I$1850,4,)) | X14: =IF(U14="","","-") | Z14: =IF(AA14="","","-") | AA14: =IF(Y14="","",VLOOKUP(Y14,'DOCUMENT TYPE'!$A$7:$C$837,2,)) | AB14: =IF(AC14="","","-") | AC14: =IF(Y14="","",VLOOKUP(Y14,'DOCUMENT TYPE'!$A$7:$C$837,3,)) | AD14: =IF(AE14=0,"","-") | AF14: =IF(AG14="","","-") | AG14: =IF(AE14="","",VLOOKUP(AE14,DISCIPLINE!$A$2:$C$845,2,)) | AH14: =IF(AI14="","","-") | AJ14: =IF(AI14="","","_") | AL14: =IF(AM14="","","-") | AN14: =IF(AM14="","","-") | AQ14: =IF(U14="","Missing input data",IF(U14="-","Missing input data",_xlfn.TEXTJOIN(,,A14,E14,J14,O14,T14:U14,AB14:AC14,AN14,(TEXT(AO14,"00")),AJ14,(TEXT(AK14,"v00")),"_",AM14))) -> Missing input data | AR14: =IF(AC14="","Missing input data",IF(AC14="-","Missing input data",LEN(AQ14))) -> Missing input data | AT14: =IF(I14="","Missing input data",IF(I14="-","Missing input data",_xlfn.TEXTJOIN(,,A14:E14,H14:I14,Z14:AA14,AD14,AG14,AH14,(TEXT(AI14,"00000")),AJ14,AM14))) -> Missing input data | AU14: =IF(I14="","Missing input data",IF(I14="-","Missing input data",LEN(AT14))) -> Missing input data
B15: =IF(C15=0,"","-") | D15: =IF(E15=0,"","-") | F15: =IF(G15=0,"","-") | H15: =IF(G15="","","-") | I15: =IF(G15="","",VLOOKUP(G15,'LEVEL-SYSTEM'!$A$2:$B$849,2,)) | J15: =IF(K15=0,"","_") | L15: =IF(M15="","","-") | M15: =IF(K15="","",VLOOKUP(K15,DISCIPLINE!$A$2:$C$845,2,)) | N15: =IF(O15="","","-") | O15: =IF(M15="","",VLOOKUP(M15,DISCIPLINE!$A$2:$C$845,2,)) | P15: =IF(K15=0,"","-") | R15: =IF(S15="","","-") | S15: =IF(Q15="","",VLOOKUP(Q15,'[1]ACTIVITY & DISCIPLINE CODE'!$F$3:$I$1862,2,)) | T15: =IF(U15="","","-") | U15: =IF(Q15="","",VLOOKUP(Q15,'[1]ACTIVITY & DISCIPLINE CODE'!$F$3:$I$1862,3,)) | V15: =IF(W15="","","-") | W15: =IF(Q15="","",VLOOKUP(Q15,'[2]ACTIVITY & DISCIPLINE CODE'!$F$3:$I$1850,4,)) | X15: =IF(U15="","","-") | Z15: =IF(AA15="","","-") | AA15: =IF(Y15="","",VLOOKUP(Y15,'DOCUMENT TYPE'!$A$7:$C$837,2,)) | AB15: =IF(AC15="","","-") | AC15: =IF(Y15="","",VLOOKUP(Y15,'DOCUMENT TYPE'!$A$7:$C$837,3,)) | AD15: =IF(AE15=0,"","-") | AF15: =IF(AG15="","","-") | AG15: =IF(AE15="","",VLOOKUP(AE15,DISCIPLINE!$A$2:$C$845,2,)) | AH15: =IF(AI15="","","-") | AJ15: =IF(AI15="","","_") | AL15: =IF(AM15="","","-") | AN15: =IF(AM15="","","-") | AQ15: =IF(U15="","Missing input data",IF(U15="-","Missing input data",_xlfn.TEXTJOIN(,,A15,E15,J15,O15,T15:U15,AB15:AC15,AN15,(TEXT(AO15,"00")),AJ15,(TEXT(AK15,"v00")),"_",AM15))) -> Missing input data | AR15: =IF(AC15="","Missing input data",IF(AC15="-","Missing input data",LEN(AQ15))) -> Missing input data | AT15: =IF(I15="","Missing input data",IF(I15="-","Missing input data",_xlfn.TEXTJOIN(,,A15:E15,H15:I15,Z15:AA15,AD15,AG15,AH15,(TEXT(AI15,"00000")),AJ15,AM15))) -> Missing input data | AU15: =IF(I15="","Missing input data",IF(I15="-","Missing input data",LEN(AT15))) -> Missing input data
B16: =IF(C16=0,"","-") | D16: =IF(E16=0,"","-") | F16: =IF(G16=0,"","-") | H16: =IF(G16="","","-") | I16: =IF(G16="","",VLOOKUP(G16,'LEVEL-SYSTEM'!$A$2:$B$849,2,)) | J16: =IF(K16=0,"","_") | L16: =IF(M16="","","-") | M16: =IF(K16="","",VLOOKUP(K16,DISCIPLINE!$A$2:$C$845,2,)) | N16: =IF(O16="","","-") | O16: =IF(M16="","",VLOOKUP(M16,DISCIPLINE!$A$2:$C$845,2,)) | P16: =IF(K16=0,"","-") | R16: =IF(S16="","","-") | S16: =IF(Q16="","",VLOOKUP(Q16,'[1]ACTIVITY & DISCIPLINE CODE'!$F$3:$I$1862,2,)) | T16: =IF(U16="","","-") | U16: =IF(Q16="","",VLOOKUP(Q16,'[1]ACTIVITY & DISCIPLINE CODE'!$F$3:$I$1862,3,)) | V16: =IF(W16="","","-") | W16: =IF(Q16="","",VLOOKUP(Q16,'[2]ACTIVITY & DISCIPLINE CODE'!$F$3:$I$1850,4,)) | X16: =IF(U16="","","-") | Z16: =IF(AA16="","","-") | AA16: =IF(Y16="","",VLOOKUP(Y16,'DOCUMENT TYPE'!$A$7:$C$837,2,)) | AB16: =IF(AC16="","","-") | AC16: =IF(Y16="","",VLOOKUP(Y16,'DOCUMENT TYPE'!$A$7:$C$837,3,)) | AD16: =IF(AE16=0,"","-") | AF16: =IF(AG16="","","-") | AG16: =IF(AE16="","",VLOOKUP(AE16,DISCIPLINE!$A$2:$C$845,2,)) | AH16: =IF(AI16="","","-") | AJ16: =IF(AI16="","","_") | AL16: =IF(AM16="","","-") | AN16: =IF(AM16="","","-") | AQ16: =IF(U16="","Missing input data",IF(U16="-","Missing input data",_xlfn.TEXTJOIN(,,A16,E16,J16,O16,T16:U16,AB16:AC16,AN16,(TEXT(AO16,"00")),AJ16,(TEXT(AK16,"v00")),"_",AM16))) -> Missing input data | AR16: =IF(AC16="","Missing input data",IF(AC16="-","Missing input data",LEN(AQ16))) -> Missing input data | AT16: =IF(I16="","Missing input data",IF(I16="-","Missing input data",_xlfn.TEXTJOIN(,,A16:E16,H16:I16,Z16:AA16,AD16,AG16,AH16,(TEXT(AI16,"00000")),AJ16,AM16))) -> Missing input data | AU16: =IF(I16="","Missing input data",IF(I16="-","Missing input data",LEN(AT16))) -> Missing input data
B17: =IF(C17=0,"","-") | D17: =IF(E17=0,"","-") | F17: =IF(G17=0,"","-") | H17: =IF(G17="","","-") | I17: =IF(G17="","",VLOOKUP(G17,'LEVEL-SYSTEM'!$A$2:$B$849,2,)) | J17: =IF(K17=0,"","_") | L17: =IF(M17="","","-") | M17: =IF(K17="","",VLOOKUP(K17,DISCIPLINE!$A$2:$C$845,2,)) | N17: =IF(O17="","","-") | O17: =IF(M17="","",VLOOKUP(M17,DISCIPLINE!$A$2:$C$845,2,)) | P17: =IF(K17=0,"","-") | R17: =IF(S17="","","-") | S17: =IF(Q17="","",VLOOKUP(Q17,'[1]ACTIVITY & DISCIPLINE CODE'!$F$3:$I$1862,2,)) | T17: =IF(U17="","","-") | U17: =IF(Q17="","",VLOOKUP(Q17,'[1]ACTIVITY & DISCIPLINE CODE'!$F$3:$I$1862,3,)) | V17: =IF(W17="","","-") | W17: =IF(Q17="","",VLOOKUP(Q17,'[2]ACTIVITY & DISCIPLINE CODE'!$F$3:$I$1850,4,)) | X17: =IF(U17="","","-") | Z17: =IF(AA17="","","-") | AA17: =IF(Y17="","",VLOOKUP(Y17,'DOCUMENT TYPE'!$A$7:$C$837,2,)) | AB17: =IF(AC17="","","-") | AC17: =IF(Y17="","",VLOOKUP(Y17,'DOCUMENT TYPE'!$A$7:$C$837,3,)) | AD17: =IF(AE17=0,"","-") | AF17: =IF(AG17="","","-") | AG17: =IF(AE17="","",VLOOKUP(AE17,DISCIPLINE!$A$2:$C$845,2,)) | AH17: =IF(AI17="","","-") | AJ17: =IF(AI17="","","_") | AL17: =IF(AM17="","","-") | AN17: =IF(AM17="","","-") | AQ17: =IF(U17="","Missing input data",IF(U17="-","Missing input data",_xlfn.TEXTJOIN(,,A17,E17,J17,O17,T17:U17,AB17:AC17,AN17,(TEXT(AO17,"00")),AJ17,(TEXT(AK17,"v00")),"_",AM17))) -> Missing input data | AR17: =IF(AC17="","Missing input data",IF(AC17="-","Missing input data",LEN(AQ17))) -> Missing input data | AT17: =IF(I17="","Missing input data",IF(I17="-","Missing input data",_xlfn.TEXTJOIN(,,A17:E17,H17:I17,Z17:AA17,AD17,AG17,AH17,(TEXT(AI17,"00000")),AJ17,AM17))) -> Missing input data | AU17: =IF(I17="","Missing input data",IF(I17="-","Missing input data",LEN(AT17))) -> Missing input data
B18: =IF(C18=0,"","-") | D18: =IF(E18=0,"","-") | F18: =IF(G18=0,"","-") | H18: =IF(G18="","","-") | I18: =IF(G18="","",VLOOKUP(G18,'LEVEL-SYSTEM'!$A$2:$B$849,2,)) | J18: =IF(K18=0,"","_") | L18: =IF(M18="","","-") | M18: =IF(K18="","",VLOOKUP(K18,DISCIPLINE!$A$2:$C$845,2,)) | N18: =IF(O18="","","-") | O18: =IF(M18="","",VLOOKUP(M18,DISCIPLINE!$A$2:$C$845,2,)) | P18: =IF(K18=0,"","-") | R18: =IF(S18="","","-") | S18: =IF(Q18="","",VLOOKUP(Q18,'[1]ACTIVITY & DISCIPLINE CODE'!$F$3:$I$1862,2,)) | T18: =IF(U18="","","-") | U18: =IF(Q18="","",VLOOKUP(Q18,'[1]ACTIVITY & DISCIPLINE CODE'!$F$3:$I$1862,3,)) | V18: =IF(W18="","","-") | W18: =IF(Q18="","",VLOOKUP(Q18,'[2]ACTIVITY & DISCIPLINE CODE'!$F$3:$I$1850,4,)) | X18: =IF(U18="","","-") | Z18: =IF(AA18="","","-") | AA18: =IF(Y18="","",VLOOKUP(Y18,'DOCUMENT TYPE'!$A$7:$C$837,2,)) | AB18: =IF(AC18="","","-") | AC18: =IF(Y18="","",VLOOKUP(Y18,'DOCUMENT TYPE'!$A$7:$C$837,3,)) | AD18: =IF(AE18=0,"","-") | AF18: =IF(AG18="","","-") | AG18: =IF(AE18="","",VLOOKUP(AE18,DISCIPLINE!$A$2:$C$845,2,)) | AH18: =IF(AI18="","","-") | AJ18: =IF(AI18="","","_") | AL18: =IF(AM18="","","-") | AN18: =IF(AM18="","","-") | AQ18: =IF(U18="","Missing input data",IF(U18="-","Missing input data",_xlfn.TEXTJOIN(,,A18,E18,J18,O18,T18:U18,AB18:AC18,AN18,(TEXT(AO18,"00")),AJ18,(TEXT(AK18,"v00")),"_",AM18))) -> Missing input data | AR18: =IF(AC18="","Missing input data",IF(AC18="-","Missing input data",LEN(AQ18))) -> Missing input data | AT18: =IF(I18="","Missing input data",IF(I18="-","Missing input data",_xlfn.TEXTJOIN(,,A18:E18,H18:I18,Z18:AA18,AD18,AG18,AH18,(TEXT(AI18,"00000")),AJ18,AM18))) -> Missing input data | AU18: =IF(I18="","Missing input data",IF(I18="-","Missing input data",LEN(AT18))) -> Missing input data
B19: =IF(C19=0,"","-") | D19: =IF(E19=0,"","-") | F19: =IF(G19=0,"","-") | H19: =IF(G19="","","-") | I19: =IF(G19="","",VLOOKUP(G19,'LEVEL-SYSTEM'!$A$2:$B$849,2,)) | J19: =IF(K19=0,"","_") | L19: =IF(M19="","","-") | M19: =IF(K19="","",VLOOKUP(K19,DISCIPLINE!$A$2:$C$845,2,)) | N19: =IF(O19="","","-") | O19: =IF(M19="","",VLOOKUP(M19,DISCIPLINE!$A$2:$C$845,2,)) | P19: =IF(K19=0,"","-") | R19: =IF(S19="","","-") | S19: =IF(Q19="","",VLOOKUP(Q19,'[1]ACTIVITY & DISCIPLINE CODE'!$F$3:$I$1862,2,)) | T19: =IF(U19="","","-") | U19: =IF(Q19="","",VLOOKUP(Q19,'[1]ACTIVITY & DISCIPLINE CODE'!$F$3:$I$1862,3,)) | V19: =IF(W19="","","-") | W19: =IF(Q19="","",VLOOKUP(Q19,'[2]ACTIVITY & DISCIPLINE CODE'!$F$3:$I$1850,4,)) | X19: =IF(U19="","","-") | Z19: =IF(AA19="","","-") | AA19: =IF(Y19="","",VLOOKUP(Y19,'DOCUMENT TYPE'!$A$7:$C$837,2,)) | AB19: =IF(AC19="","","-") | AC19: =IF(Y19="","",VLOOKUP(Y19,'DOCUMENT TYPE'!$A$7:$C$837,3,)) | AD19: =IF(AE19=0,"","-") | AF19: =IF(AG19="","","-") | AG19: =IF(AE19="","",VLOOKUP(AE19,DISCIPLINE!$A$2:$C$845,2,)) | AH19: =IF(AI19="","","-") | AJ19: =IF(AI19="","","_") | AL19: =IF(AM19="","","-") | AN19: =IF(AM19="","","-") | AQ19: =IF(U19="","Missing input data",IF(U19="-","Missing input data",_xlfn.TEXTJOIN(,,A19,E19,J19,O19,T19:U19,AB19:AC19,AN19,(TEXT(AO19,"00")),AJ19,(TEXT(AK19,"v00")),"_",AM19))) -> Missing input data | AR19: =IF(AC19="","Missing input data",IF(AC19="-","Missing input data",LEN(AQ19))) -> Missing input data | AT19: =IF(I19="","Missing input data",IF(I19="-","Missing input data",_xlfn.TEXTJOIN(,,A19:E19,H19:I19,Z19:AA19,AD19,AG19,AH19,(TEXT(AI19,"00000")),AJ19,AM19))) -> Missing input data | AU19: =IF(I19="","Missing input data",IF(I19="-","Missing input data",LEN(AT19))) -> Missing input data
B20: =IF(C20=0,"","-") | D20: =IF(E20=0,"","-") | F20: =IF(G20=0,"","-") | H20: =IF(G20="","","-") | I20: =IF(G20="","",VLOOKUP(G20,'LEVEL-SYSTEM'!$A$2:$B$849,2,)) | J20: =IF(K20=0,"","_") | L20: =IF(M20="","","-") | M20: =IF(K20="","",VLOOKUP(K20,DISCIPLINE!$A$2:$C$845,2,)) | N20: =IF(O20="","","-") | O20: =IF(M20="","",VLOOKUP(M20,DISCIPLINE!$A$2:$C$845,2,)) | P20: =IF(K20=0,"","-") | R20: =IF(S20="","","-") | S20: =IF(Q20="","",VLOOKUP(Q20,'[1]ACTIVITY & DISCIPLINE CODE'!$F$3:$I$1862,2,)) | T20: =IF(U20="","","-") | U20: =IF(Q20="","",VLOOKUP(Q20,'[1]ACTIVITY & DISCIPLINE CODE'!$F$3:$I$1862,3,)) | V20: =IF(W20="","","-") | W20: =IF(Q20="","",VLOOKUP(Q20,'[2]ACTIVITY & DISCIPLINE CODE'!$F$3:$I$1850,4,)) | X20: =IF(U20="","","-") | Z20: =IF(AA20="","","-") | AA20: =IF(Y20="","",VLOOKUP(Y20,'DOCUMENT TYPE'!$A$7:$C$837,2,)) | AB20: =IF(AC20="","","-") | AC20: =IF(Y20="","",VLOOKUP(Y20,'DOCUMENT TYPE'!$A$7:$C$837,3,)) | AD20: =IF(AE20=0,"","-") | AF20: =IF(AG20="","","-") | AG20: =IF(AE20="","",VLOOKUP(AE20,DISCIPLINE!$A$2:$C$845,2,)) | AH20: =IF(AI20="","","-") | AJ20: =IF(AI20="","","_") | AL20: =IF(AM20="","","-") | AN20: =IF(AM20="","","-") | AQ20: =IF(U20="","Missing input data",IF(U20="-","Missing input data",_xlfn.TEXTJOIN(,,A20,E20,J20,O20,T20:U20,AB20:AC20,AN20,(TEXT(AO20,"00")),AJ20,(TEXT(AK20,"v00")),"_",AM20))) -> Missing input data | AR20: =IF(AC20="","Missing input data",IF(AC20="-","Missing input data",LEN(AQ20))) -> Missing input data | AT20: =IF(I20="","Missing input data",IF(I20="-","Missing input data",_xlfn.TEXTJOIN(,,A20:E20,H20:I20,Z20:AA20,AD20,AG20,AH20,(TEXT(AI20,"00000")),AJ20,AM20))) -> Missing input data | AU20: =IF(I20="","Missing input data",IF(I20="-","Missing input data",LEN(AT20))) -> Missing input data
B21: =IF(C21=0,"","-") | D21: =IF(E21=0,"","-") | F21: =IF(G21=0,"","-") | H21: =IF(G21="","","-") | I21: =IF(G21="","",VLOOKUP(G21,'LEVEL-SYSTEM'!$A$2:$B$849,2,)) | J21: =IF(K21=0,"","_") | L21: =IF(M21="","","-") | M21: =IF(K21="","",VLOOKUP(K21,DISCIPLINE!$A$2:$C$845,2,)) | N21: =IF(O21="","","-") | O21: =IF(M21="","",VLOOKUP(M21,DISCIPLINE!$A$2:$C$845,2,)) | P21: =IF(K21=0,"","-") | R21: =IF(S21="","","-") | S21: =IF(Q21="","",VLOOKUP(Q21,'[1]ACTIVITY & DISCIPLINE CODE'!$F$3:$I$1862,2,)) | T21: =IF(U21="","","-") | U21: =IF(Q21="","",VLOOKUP(Q21,'[1]ACTIVITY & DISCIPLINE CODE'!$F$3:$I$1862,3,)) | V21: =IF(W21="","","-") | W21: =IF(Q21="","",VLOOKUP(Q21,'[2]ACTIVITY & DISCIPLINE CODE'!$F$3:$I$1850,4,)) | X21: =IF(U21="","","-") | Z21: =IF(AA21="","","-") | AA21: =IF(Y21="","",VLOOKUP(Y21,'DOCUMENT TYPE'!$A$7:$C$837,2,)) | AB21: =IF(AC21="","","-") | AC21: =IF(Y21="","",VLOOKUP(Y21,'DOCUMENT TYPE'!$A$7:$C$837,3,)) | AD21: =IF(AE21=0,"","-") | AF21: =IF(AG21="","","-") | AG21: =IF(AE21="","",VLOOKUP(AE21,DISCIPLINE!$A$2:$C$845,2,)) | AH21: =IF(AI21="","","-") | AJ21: =IF(AI21="","","_") | AL21: =IF(AM21="","","-") | AN21: =IF(AM21="","","-") | AQ21: =IF(U21="","Missing input data",IF(U21="-","Missing input data",_xlfn.TEXTJOIN(,,A21,E21,J21,O21,T21:U21,AB21:AC21,AN21,(TEXT(AO21,"00")),AJ21,(TEXT(AK21,"v00")),"_",AM21))) -> Missing input data | AR21: =IF(AC21="","Missing input data",IF(AC21="-","Missing input data",LEN(AQ21))) -> Missing input data | AT21: =IF(I21="","Missing input data",IF(I21="-","Missing input data",_xlfn.TEXTJOIN(,,A21:E21,H21:I21,Z21:AA21,AD21,AG21,AH21,(TEXT(AI21,"00000")),AJ21,AM21))) -> Missing input data | AU21: =IF(I21="","Missing input data",IF(I21="-","Missing input data",LEN(AT21))) -> Missing input data
B22: =IF(C22=0,"","-") | D22: =IF(E22=0,"","-") | F22: =IF(G22=0,"","-") | H22: =IF(G22="","","-") | I22: =IF(G22="","",VLOOKUP(G22,'LEVEL-SYSTEM'!$A$2:$B$849,2,)) | J22: =IF(K22=0,"","_") | L22: =IF(M22="","","-") | M22: =IF(K22="","",VLOOKUP(K22,DISCIPLINE!$A$2:$C$845,2,)) | N22: =IF(O22="","","-") | O22: =IF(M22="","",VLOOKUP(M22,DISCIPLINE!$A$2:$C$845,2,)) | P22: =IF(K22=0,"","-") | R22: =IF(S22="","","-") | S22: =IF(Q22="","",VLOOKUP(Q22,'[1]ACTIVITY & DISCIPLINE CODE'!$F$3:$I$1862,2,)) | T22: =IF(U22="","","-") | U22: =IF(Q22="","",VLOOKUP(Q22,'[1]ACTIVITY & DISCIPLINE CODE'!$F$3:$I$1862,3,)) | V22: =IF(W22="","","-") | W22: =IF(Q22="","",VLOOKUP(Q22,'[2]ACTIVITY & DISCIPLINE CODE'!$F$3:$I$1850,4,)) | X22: =IF(U22="","","-") | Z22: =IF(AA22="","","-") | AA22: =IF(Y22="","",VLOOKUP(Y22,'DOCUMENT TYPE'!$A$7:$C$837,2,)) | AB22: =IF(AC22="","","-") | AC22: =IF(Y22="","",VLOOKUP(Y22,'DOCUMENT TYPE'!$A$7:$C$837,3,)) | AD22: =IF(AE22=0,"","-") | AF22: =IF(AG22="","","-") | AG22: =IF(AE22="","",VLOOKUP(AE22,DISCIPLINE!$A$2:$C$845,2,)) | AH22: =IF(AI22="","","-") | AJ22: =IF(AI22="","","_") | AL22: =IF(AM22="","","-") | AN22: =IF(AM22="","","-") | AQ22: =IF(U22="","Missing input data",IF(U22="-","Missing input data",_xlfn.TEXTJOIN(,,A22,E22,J22,O22,T22:U22,AB22:AC22,AN22,(TEXT(AO22,"00")),AJ22,(TEXT(AK22,"v00")),"_",AM22))) -> Missing input data | AR22: =IF(AC22="","Missing input data",IF(AC22="-","Missing input data",LEN(AQ22))) -> Missing input data | AT22: =IF(I22="","Missing input data",IF(I22="-","Missing input data",_xlfn.TEXTJOIN(,,A22:E22,H22:I22,Z22:AA22,AD22,AG22,AH22,(TEXT(AI22,"00000")),AJ22,AM22))) -> Missing input data | AU22: =IF(I22="","Missing input data",IF(I22="-","Missing input data",LEN(AT22))) -> Missing input data
B23: =IF(C23=0,"","-") | D23: =IF(E23=0,"","-") | F23: =IF(G23=0,"","-") | H23: =IF(G23="","","-") | I23: =IF(G23="","",VLOOKUP(G23,'LEVEL-SYSTEM'!$A$2:$B$849,2,)) | J23: =IF(K23=0,"","_") | L23: =IF(M23="","","-") | M23: =IF(K23="","",VLOOKUP(K23,DISCIPLINE!$A$2:$C$845,2,)) | N23: =IF(O23="","","-") | O23: =IF(M23="","",VLOOKUP(M23,DISCIPLINE!$A$2:$C$845,2,)) | P23: =IF(K23=0,"","-") | R23: =IF(S23="","","-") | S23: =IF(Q23="","",VLOOKUP(Q23,'[1]ACTIVITY & DISCIPLINE CODE'!$F$3:$I$1862,2,)) | T23: =IF(U23="","","-") | U23: =IF(Q23="","",VLOOKUP(Q23,'[1]ACTIVITY & DISCIPLINE CODE'!$F$3:$I$1862,3,)) | V23: =IF(W23="","","-") | W23: =IF(Q23="","",VLOOKUP(Q23,'[2]ACTIVITY & DISCIPLINE CODE'!$F$3:$I$1850,4,)) | X23: =IF(U23="","","-") | Z23: =IF(AA23="","","-") | AA23: =IF(Y23="","",VLOOKUP(Y23,'DOCUMENT TYPE'!$A$7:$C$837,2,)) | AB23: =IF(AC23="","","-") | AC23: =IF(Y23="","",VLOOKUP(Y23,'DOCUMENT TYPE'!$A$7:$C$837,3,)) | AD23: =IF(AE23=0,"","-") | AF23: =IF(AG23="","","-") | AG23: =IF(AE23="","",VLOOKUP(AE23,DISCIPLINE!$A$2:$C$845,2,)) | AH23: =IF(AI23="","","-") | AJ23: =IF(AI23="","","_") | AL23: =IF(AM23="","","-") | AN23: =IF(AM23="","","-") | AQ23: =IF(U23="","Missing input data",IF(U23="-","Missing input data",_xlfn.TEXTJOIN(,,A23,E23,J23,O23,T23:U23,AB23:AC23,AN23,(TEXT(AO23,"00")),AJ23,(TEXT(AK23,"v00")),"_",AM23))) -> Missing input data | AR23: =IF(AC23="","Missing input data",IF(AC23="-","Missing input data",LEN(AQ23))) -> Missing input data | AT23: =IF(I23="","Missing input data",IF(I23="-","Missing input data",_xlfn.TEXTJOIN(,,A23:E23,H23:I23,Z23:AA23,AD23,AG23,AH23,(TEXT(AI23,"00000")),AJ23,AM23))) -> Missing input data | AU23: =IF(I23="","Missing input data",IF(I23="-","Missing input data",LEN(AT23))) -> Missing input data
... B1000: =IF(C1000=0,"","-") | D1000: =IF(E1000=0,"","-") | F1000: =IF(G1000=0,"","-") | H1000: =IF(G1000="","","-") | I1000: =IF(G1000="","",VLOOKUP(G1000,'LEVEL-SYSTEM'!$A$2:$B$849,2,)) | J1000: =IF(K1000=0,"","_") | L1000: =IF(M1000="","","-") | M1000: =IF(K1000="","",VLOOKUP(K1000,DISCIPLINE!$A$2:$C$845,2,)) | N1000: =IF(O1000="","","-") | O1000: =IF(M1000="","",VLOOKUP(M1000,DISCIPLINE!$A$2:$C$845,2,)) | P1000: =IF(K1000=0,"","-") | R1000: =IF(S1000="","","-") | S1000: =IF(Q1000="","",VLOOKUP(Q1000,'[1]ACTIVITY & DISCIPLINE CODE'!$F$3:$I$1862,2,)) | T1000: =IF(U1000="","","-") | U1000: =IF(Q1000="","",VLOOKUP(Q1000,'[1]ACTIVITY & DISCIPLINE CODE'!$F$3:$I$1862,3,)) | V1000: =IF(W1000="","","-") | W1000: =IF(Q1000="","",VLOOKUP(Q1000,'[2]ACTIVITY & DISCIPLINE CODE'!$F$3:$I$1850,4,)) | X1000: =IF(U1000="","","-") | Z1000: =IF(AA1000="","","-") | AA1000: =IF(Y1000="","",VLOOKUP(Y1000,'DOCUMENT TYPE'!$A$7:$C$837,2,)) | AB1000: =IF(AC1000="","","-") | AC1000: =IF(Y1000="","",VLOOKUP(Y1000,'DOCUMENT TYPE'!$A$7:$C$837,3,)) | AD1000: =IF(AE1000=0,"","-") | AF1000: =IF(AG1000="","","-") | AG1000: =IF(AE1000="","",VLOOKUP(AE1000,DISCIPLINE!$A$2:$C$845,2,)) | AH1000: =IF(AI1000="","","-") | AJ1000: =IF(AI1000="","","_") | AL1000: =IF(AM1000="","","-") | AN1000: =IF(AM1000="","","-") | AQ1000: =IF(U1000="","Missing input data",IF(U1000="-","Missing input data",_xlfn.TEXTJOIN(,,A1000,E1000,J1000,O1000,T1000:U1000,AB1000:AC1000,AN1000,(TEXT(AO1000,"00")),AJ1000,(TEXT(AK1000,"v00")),"_",AM1000))) -> Missing input data | AR1000: =IF(AC1000="","Missing input data",IF(AC1000="-","Missing input data",LEN(AQ1000))) -> Missing input data | AT1000: =IF(I1000="","Missing input data",IF(I1000="-","Missing input data",_xlfn.TEXTJOIN(,,A1000:E1000,H1000:I1000,Z1000:AA1000,AD1000,AG1000,AH1000,(TEXT(AI1000,"00000")),AJ1000,AM1000))) -> Missing input data | AU1000: =IF(I1000="","Missing input data",IF(I1000="-","Missing input data",LEN(AT1000))) -> Missing input data

Sheet PROJECT ID
A1: CODE | B1: DESCRIPTION
A2: RBGL | B2: RBR Governance - Training Material, Templates, Internal Governance documents (Manuals, Procedures, Policies etc.)
A3: RBCR | B3: RBR Corporate* (Legal, Financial, HR, Procurement, etc.)
A4: RB### | B4: RBR Corporate* Projects (with existing assigned Project ID)
A5: RBEE | B5: RB Estonian Branch (RBE Administrative and overall RB Estonia Branch related documents that are related to multiple contracts)
A6: EE1100 | B6: RBGP General and Design Documents specific to Soodevahe-Muuga mainline
A7: EE1401 | B7: RBGP General and Design Documents specific to Muuga Freight Terminal
A8: EE2100 | B8: RBGP General and Design Documents specific to Tallinn-Pärnu mainline
A9: EE2302 | B9: RBGP General and Design Documents specific to Tallinn-Ülemiste Station
A10: EE2100 | B10: RBGP General and Design Documents specific to Alliance I
A11: EE2100 | B11: RBGP General and Design Documents specific to Harju I
A12: EE2100 | B12: RBGP General and Design Documents specific to Harju V
... A45: RBDL | B45: RBGP Project Delivery (generic, involving Design AND Construction) without a Project ID

Sheet ORIGINATOR_SUPPLIER
A1: CODE | B1: NAME | C1: Role assigned
A2: AFR | B2: Afry
A3: ALL | B3: Allspark
A4: ARD | B4: Ardanuy
A5: PLU | B5: Arhitektuuribüroo PLUSS (ET)
A6: YIT | B6: AS YIT Eesti
A7: ATE | B7: Atemo OÜ
A8: BGS | B8: Bouygues Travaux Publics
A9: BMX | B9: Budimex SA
A10: ENS | B10: Enersense AS
A11: GRK | B11: GRK
A12: HPT | B12: Hepta Group Energy OÜ
A13: INF | B13: INF INFRA OÜ
... A40: WSP | B40: WSP

Sheet VOLUME_SYSTEM
A1: IN FORCE CODE | B1: MD CODE | C1: DTD | D1: RBR-Functional classification | E1: NAME / TYPE | F1: COUNTRY | G1: PD code | H1: PD Section | I1: Municipality | J1: WGS84 Long X Coordinate | K1: WGS84 Lat Y Coordinate | L1: Characteristics of Crossing / Road / Utility | M1: Affected party | N1: PD_km | O1: Type of data | P1: Date | Q1: Order | S1: Order with roads | T1: Archive??? | U1: Archive | V1: New
A2: 000000 | B2: 000000 | E2: No Volume applicable | F2: EE | Q2: 1 | R2: 1
A3: BR0020 | B3: BR0020 | D3: CV-BR-RWBG-00 | E3: Bridge-Railway | F3: EE | H3: 3 | J3: 59.229465 | K3: 24.726774 | L3: Construction Object 01 - Railway Bridge - Kroodi stream RB (09-BR13, BR0020) | N3: 1+450 | O3: Bridge | Q3: 2 | R3: 2
A4: BR0022 | B4: BR0022 | D4: CV-BR-RWBG-00 | E4: Bridge-Railway | F4: EE | H4: 3 | J4: 59.465616 | K4: 24.979142 | L4: Construction Object 02 - Railway Bridge - Kroodi stream 1520 (BR0022) | N4: 1+450 | O4: Bridge | Q4: 3 | R4: 3
A5: BR0030 | B5: BR0030 | D5: CV-TU-TUNL-00 | E5: Tunnel | F5: EE | H5: 3 | J5: 59.452745 | K5: 24.980197 | L5: Construction Object 01 - Railway Tunnel Maardu (09-BR11, BR0030) | N5: 2+300 - 3+300 | O5: Tunnel | Q5: 4 | R5: 4
A6: BR0040 | B6: BR0040 | D6: CV-BR-UPSS-RD | E6: Underpass-Road | F6: EE | H6: 3 | J6: 59.446618 | K6: 24.925558 | L6: Construction Object 01 - Railway Bridge - T1 Tallinn-Narva Road (09-BR10, BR0040)/ Peterburi tee underpass | N6: 5+940 - 6+120 | O6: Underpass | Q6: 5 | R6: 5
A7: BR0050 | B7: BR0050 | D7: CV-BR-RWBG-00 | E7: Bridge-Railway | F7: EE | H7: 3 | J7: 59.213138 | K7: 24.740657 | L7: Construction Object 01 - Railway Bridge - Pirita River (09-BR08, BR0050) | N7: 7+390 - 7+500 | O7: Bridge | Q7: 6 | R7: 6
A8: BR0051 | B8: BR0051 | C8: BR0051 | D8: CV-BR-UPSS-PD | E8: Underpass-Pedestrian | F8: EE | H8: 1 | J8: 59.423326 | K8: 24.791768 | L8: Tunnel nr 5 | N8: -1+845 | O8: Underpass | Q8: 7 | R8: 7
A9: BR0053 | B9: BR0053 | D9: CV-BR-RWBG-00 | E9: Bridge-Railway | F9: EE | H9: 3 | J9: 59.435588 | K9: 24.926448 | L9: 1520 Pirita river bridge reconstruction | N9: 7+380 | O9: Bridge | P9: 25.07.2025 | Q9: 8 | R9: 8
A10: BR0055 | B10: BR0055 | D10: CV-BR-OPSS-RD | E10: Overpass-Road | F10: EE | H10: 1 | J10: 59.421277 | K10: 24.84155 | L10: Smuuli overpass | N10: 0+993 | O10: Overpass | Q10: 9 | R10: 9
A11: BR0060 | B11: BR0060 | D11: CV-TU-TUNL-00 | E11: Tunnel | F11: EE | H11: 1 | J11: 59.409778 | K11: 24.910953 | L11: Construction Object 01 - Railway Tunnel - 1520 Tracks & 11290 Tallinn-Lagedi Road (09-BR04, BR0060) | N11: 10+200 - 11+595 | O11: Tunnel | Q11: 10 | R11: 10
A12: BR0070 | B12: BR0070 | D12: CV-BR-OPSS-RD | E12: Overpass-Road | F12: EE | H12: 1 | J12: 59.465595 | K12: 24.978824 | L12: Overpass 11290 Tallinn-Lagedi | N12: 5+054 | O12: Overpass | Q12: 11 | R12: 11
A13: BR0075 | B13: BR0075 | D13: CV-BR-RWBG-00 | E13: Bridge-Railway | F13: EE | H13: 1 | J13: 59.465616 | K13: 24.979142 | L13: Vaskjala Ülemiste water channel bridge | N13: 8+624 | O13: Bridge | Q13: 12 | R13: 12
A14: BR0130 | B14: BR0130 | D14: CV-BR-RWBG-00 | E14: Bridge-Railway | F14: EE | H14: 1 | J14: 59.362144 | K14: 24.788934 | L14: Railway Bridge Kurnaoja Road & Kurna stream | M14: Noise barrier asociated to road | N14: 15+494 | O14: Bridge | Q14: 13 | R14: 13
A15: BR0143 | C15: BR0143 | D15: CV-BR-OPSS-RW | E15: Overpass-Railway | F15: EE | H15: 2 | J15: 59.268391 | K15: 24.693406 | L15: Männiku Pileslab 1 | N15: 2+042-3+132 | O15: Overpass | Q15: 14 | R15: 14
A16: BR0146 | C16: BR0146 | D16: CV-BR-OPSS-RW | E16: Overpass-Railway | F16: EE | H16: 2 | J16: 59.25627 | K16: 24.699371 | L16: Männiku Pileslab 2 | N16: 4+250-6+042 | O16: Overpass | Q16: 15 | R16: 15
A17: BR0150 | C17: BR0150 | D17: CV-BR-OPSS-RD | E17: Overpass-Road | F17: EE | H17: 2 | J17: 59.312248 | K17: 24.736272 | L17: Saustinõmme overpass | N17: 6+265 | O17: Overpass | Q17: 16 | R17: 16
A18: BR0160 | B18: BR0160 | D18: CV-BR-RWBG-00 | E18: Bridge-Railway | F18: EE | H18: 2 | J18: 59.435373 | K18: 24.927118 | L18: New Vääna River Bridge | N18: 9+446 | O18: Bridge | Q18: 17 | R18: 17
A19: BR0165 | B19: BR0165 | D19: CV-BR-RWBG-00 | E19: Bridge-Railway | F19: EE | H19: 2 | J19: 59.423326 | K19: 24.791768 | L19: Old Vääna River Bridge | N19: 9+811 | O19: Bridge | Q19: 18 | R19: 18
A20: BR0170 | B20: BR0170 | D20: CV-BR-UPSS-RD | E20: Underpass-Road | F20: EE | H20: 2 | J20: 59.287252 | K20: 24.69577 | L20: Railway Bridge Soo Road | N20: 9+943 | O20: Bridge | Q20: 19 | R20: 19
A21: BR0230 | B21: BR0230 | D21: CV-BR-OPSS-RD | E21: Overpass-Road | F21: EE | H21: 3 | J21: 59.229896 | K21: 24.727629 | L21: Construction Object 02 - Road Bridge - Altmetsa Road (BR0230) | N21: 1+120 | O21: Overpass | Q21: 20 | R21: 20
A22: BR0235 | B22: BR0235 | D22: CV-BR-OPSS-RD | E22: Overpass-Road | F22: EE | H22: 3 | J22: 59.455088 | K22: 24.980685 | L22: Kroodi I overpass | N22: 2+496 | O22: Overpass | Q22: 21 | R22: 21
A23: BR0240 | B23: BR0240 | D23: CV-BR-UPSS-PD | E23: Underpass-Pedestrian | F23: EE | H23: 3 | J23: 59.215059 | K23: 24.736166 | L23: Construction Object 02 - Road Underpass - Nehatu Road (08-BR09, BR0240) | N23: 6+420 | O23: Underpass | Q23: 22 | R23: 22
A24: BR0250 | B24: BR0250 | D24: CV-BR-OPSS-RD | E24: Overpass-Road | F24: EE | H24: 3 | J24: 59.425401 | K24: 24.920653 | L24: Väo overpass | N24: 8+613 | O24: Overpass | Q24: 23 | R24: 23
A25: BR0256 | B25: BR0256 | D25: CV-BR-OPSS-RD | E25: Overpass-Road | F25: EE | H25: 3 | J25: 59.481312 | K25: 24.973026 | L25: Construction Object 02 - Veneküla overpass - (09-BR05, BR0256) | N25: 9+500 | O25: Overpass | Q25: 24 | R25: 24
A26: BR0258 | B26: BR0258 | D26: CV-BR-OPSS-RD | E26: Overpass-Road | F26: EE | H26: 3 | J26: 59.414407 | K26: 24.90819 | L26: Varivere Road over 1520 Railway Line | N26: 2+260 | O26: Overpass | Q26: 25 | R26: 25
A27: BR0260 | B27: BR0260 | D27: CV-BR-OPSS-RD | E27: Overpass-Road | F27: EE | H27: 3 | J27: 59.214532 | K27: 24.735149 | L27: Construction Object 02 - Road overpass - Varivere Road (09-BR05, BR0260) /Lepiku overpass | N27: 10+080 | O27: Overpass | Q27: 26 | R27: 26
A28: BR0280 | B28: BR0280 | C28: BR0280 | D28: CV-BR-OPSS-RD | E28: Overpass-Road | F28: EE | H28: 1 | J28: 59.377591 | K28: 24.894526 | L28: Overpass 11113 Assaku_Jüri | N28: 9+154 | O28: Overpass | Q28: 27 | R28: 27
A29: BR0290 | B29: BR0290 | D29: CV-BR-OPSS-RD | E29: Overpass-Road | F29: EE | H29: 1 | J29: 59.341171 | K29: 24.762322 | L29: Overpass 11330 Järveküla-Jüri | N29: 11+236 | O29: Overpass | Q29: 28 | R29: 28
A30: BR0300 | B30: BR0300 | D30: CV-BR-OPSS-RD | E30: Overpass-Road | F30: EE | H30: 1 | J30: 59.288346 | K30: 24.696555 | L30: Overpass T2 Tallinn-Tartu-Võru-Luhamaa | N30: 11+483 | O30: Overpass | Q30: 29 | R30: 29
A31: BR0310 | B31: BR0310 | D31: CV-BR-OPSS-RD | E31: Overpass-Road | F31: EE | H31: 1 | J31: 59.455088 | K31: 24.980685 | L31: Overpass Rukki Local Road | N31: 11+665 | O31: Overpass | Q31: 30 | R31: 30
A32: BR0320 | B32: BR0320 | D32: CV-BR-OPSS-RD | E32: Overpass-Road | F32: EE | H32: 1 | J32: 59.443397 | K32: 24.92445 | L32: Uuesalu Overpass / Põdra Local Road | N32: 13+650 | O32: Overpass | Q32: 31 | R32: 31
A33: BR0345 | B33: BR0345 | D33: CV-BR-OPSS-RD | E33: Overpass-Road | F33: EE | H33: 2 | J33: 59.425401 | K33: 24.920653 | L33: Overpass T15 Tallinn-Rapla-Türi (08-BR11c) | M33: ON HOLD | N33: 0+742 | O33: Overpass | Q33: 32 | R33: 32
A34: BR0347 | C34: BR0347 | D34: CV-BR-OPSS-RD | E34: Overpass-Road | F34: EE | H34: 2 | J34: 59.357542 | K34: 24.768641 | L34: Raudalu overpass | M34: BR0350 | N34: 0+863 | O34: Overpass | Q34: 33 | R34: 33
A35: BR0350 | B35: BR0350 | D35: CV-BR-OPSS-RD | E35: Overpass-Road | F35: EE | H35: 2 | J35: 59.419025 | K35: 24.912046 | L35: Overpass T15 Tallinn-Rapla-Türi (08-BR11a) | N35: 1+496 | O35: Overpass | Q35: 34 | R35: 34
A36: BR0360 | B36: BR0360 | D36: CV-BR-OPSS-RD | E36: Overpass-Road | F36: EE | H36: 2 | J36: 59.414407 | K36: 24.90819 | L36: Overpass 11342 Saku-Tõdva | N36: 11+462 | O36: Overpass | Q36: 35 | R36: 35
A37: BR0370 | B37: BR0370 | D37: CV-BR-OPSS-RD | E37: Overpass-Road | F37: EE | H37: 2 | J37: 59.369927 | K37: 24.856713 | L37: Overpass 11240 Tõdva-Hageri | N37: 13+518 | O37: Overpass | Q37: 36 | R37: 36
A38: BR0380 | B38: BR0380 | D38: CV-BR-OPSS-RD | E38: Overpass-Road | F38: EE | H38: 2 | J38: 59.367668 | K38: 24.819121 | L38: Overpass 11152 Kirdalu-Kiisa | N38: 16+244 | O38: Overpass | Q38: 37 | R38: 37
A39: BR0390 | B39: BR0390 | D39: CV-BR-OPSS-RD | E39: Overpass-Road | F39: EE | H39: 2 | J39: 59.357542 | K39: 24.768641 | L39: Overpass 11154 Tagadi-Kurtna | N39: 16+986 | O39: Overpass | Q39: 38 | R39: 38
A40: BR0543 | B40: BR0543 | D40: CV-BR-OPSS-PD | E40: Overpass-Pedestrian | F40: EE | H40: 2 | J40: 59.421028 | K40: 24.842346 | L40: Overpass Pedestrian crossing (08-BR11b) | N40: 1+020 | O40: Overpass | Q40: 39 | R40: 39
...

Sheet LEVEL-SYSTEM
A1: LEVEL/SYSTEM | B1: CODE
A2: Without Reference | B2: XX
A3: Multiple Levels | B3: ZZ
A4: Level 1 above Land Level | B4: 01
A5: Level 2 above Land Level | B5: 02
A6: Level n above Land Level | B6: 0n
A7: Level coincident with the ground surface, Land Level. | B7: LL
A8: Mezzanine above Level 1 | B8: M1
A9: Roofing | B9: RF
A10: Level 1 Below Land Level | B10: S1
A11: Level 2 Below Land Level | B11: S2
A12: Level n Below Land Level | B12: Sn
... A254: Rolling Stock | B254: RL

Sheet DOCUMENT TYPE
A1: DOCUMENT TYPE DESCRIPTION | B1: RBR CODE | C1: EE file name relevant | D1: Descriptions
A2: Act (e.g.: Inventory, accident at workplace (H&S)) | B2: ACT | C2: 9 | D2: A legally binding document or report related to workplace health and safety incidents or statutory compliance. | F2: FOR INFORMATION
A3: Asset Data Dictionary | B3: AD2 | C3: 9 | D3: Asset Information Model (AIM) requirements | F3: EE document types
A4: Asset Data Dictionary Definition Documents (AD4s) | B4: AD4 | C4: 9 | D4: Asset Information Model (AIM) requirement documents | F4: 0 | G4: Ülddokumendid (tiitelleht, sisukord, dokumentide nimekiri jms) | H4: General documents (title page, table of contents, list of documents, etc.)
A5: Agreement | B5: AGR | C5: 2 | D5: A formal contract between parties outlining terms and conditions related to project delivery or services. | F5: 1 | G5: Lähtedokumendid (projekteerimistingimused, tehnilised tingimused jms) | H5: Reference documents (design specifications, technical conditions, etc.)
A6: As-built information Models | B6: AIM | C6: 9 | D6: Digital representations of the built asset, reflecting its actual constructed state. | F6: 2 | G6: Kooskõlastused (kooskõlastuste koondtabel, kooskõlastuslehed jms) | H6: Coordinations (summary table of coordination, coordination letters, etc.)
A7: Amendment | B7: AMN | C7: 9 | D7: A document that officially modifies or updates existing project agreements or specifications. | F7: 3 | G7: Seletuskirjad | H7: Explanatory notes
A8: Application | B8: APL | C8: 9 | D8: A formal written request for permission or approval related to project activities. | F8: 4 | G8: Asendiplaani joonised (välisosa plaanijoonised) | H8: Drawings of the position plan (external plane layouts)
A9: Appeal | B9: APP | C9: 9 | D9: A documented request to review or reconsider a prior decision or assessment. | F9: 5 | G9: Ehitise üldised plaanijoonised (horisontaalsed üldjoonised, sh üldskeemid) | H9: General layout of the building (horizontal general drawings, including general layouts)
A10: Assessment | B10: ASM | C10: 2 | D10: A documented evaluation of performance, risk, or compliance. | F10: 6 | G10: Ehitise üldised vaated, lõiked, pikiprofiilid (vertikaalsed üldjoonised) | H10: General views, cuts, longitudinal profiles of the building (vertical drawings)
A11: Audit (e.g.: Internal, External, Quality Assurance) | B11: AUD | C11: 9 | D11: An independent examination of systems, procedures, or data to ensure compliance and effectiveness. | F11: 7 | G11: Muud joonised (sõlmed, detailid jms) | H11: Other drawings (nodes, details, etc.)
A12: Bill of Lading | B12: BIL | C12: 9 | D12: A transport document detailing the shipment of goods and their intended delivery. | F12: 8 | G12: Spetsifikatsioonid, mahtude loetelud jms | H12: Specifications, volumes, etc.
A13: BIM Model | B13: BIM | C13: 9 | D13: A structured digital representation of physical and functional characteristics of a built asset for shared project understanding. | F13: 9 | G13: Lisad (kõik muud lisatavad dokumendid) | H13: Extras (all other documents to be added)
A14: Bill of Quantity (e.g.: Construction products, Construction Works, Equipment, etc) | B14: BOQ | C14: 8 | D14: A document itemizing materials, parts, and labor with associated costs for construction.
A15: Bond | B15: BND | C15: 9 | D15: A legal guarantee or financial security ensuring project obligations are fulfilled.
A16: Calculation | B16: CAL | C16: 9 | D16: Documented numerical or engineering analyses supporting design or decision-making.
A17: Certificate (e.g.: registration, suppliers) | B17: CER | C17: 9 | D17: An official record validating compliance, registration, or approval status.
A18: Change Request Notice | B18: CRN | C18: 9 | D18: A formal request to alter scope, time, or cost aspects of the project.
A19: Chart (e.g.: Accounting) | B19: CHA | C19: 9 | D19: A visual data representation used for analysis, often related to budgets or schedules.
A20: Communication (e.g.: letter, email, fax) | B20: COM | C20: 9 | D20: Official project-related correspondence exchanged between stakeholders.
A21: Comment sheet | B21: CRS | C21: 9 | D21: A document collecting stakeholder feedback or observations on project outputs.
A22: Consent | B22: CSN | C22: 0 | D22: A written permission or approval from an authority or stakeholder.
A23: Corrective Action Report | B23: CAR | C23: 8 | D23: A document outlining steps taken to rectify non-conformances or issues.
A24: Decision (of Companies Registers) | B24: DEC | C24: 2 | D24: An official resolution or outcome recorded by a regulatory body or internal authority.
A25: Deed | B25: DED | C25: 9 | D25: A legally binding document that transfers rights or obligations.
... A86: XREF file | B86: XRF | C86: 4 | D86: A reference drawing or model file externally linked to the main document or model.
A87: To be continued if required. Any code and description shall be agreed with the Client.

Sheet DISCIPLINE
A1: ROLES | B1: CODE
A2: Architecture | B2: A
A3: Building Surveying, Construction and Site Management | B3: B
A4: Civil Engineering | B4: C
A5: Drainage, Roads and Highways Engineering | B5: D
A6: Electrical Engineering | B6: E
A7: Facilities and Asset Management | B7: F
A8: Geographical & Land Surveying (+GIS) | B8: G
A9: Heating, Ventilation and Air Conditioning Design | B9: H
A10: Interior Design and Art | B10: I
A11: System Engineering and Assurance | B11: J
A12: Client, Stakeholder, IBs and BENs | B12: K
... A27: General RB Rail (Corporate Part) | B27: Z
A29: To be continued if required. Any code and description shall be agreed with the Client.

Sheet PROJECT STAGE
A1: STAGE DESCRIPTION | B1: RBR CODE | C1: EE CODE | D1: Staadium
A2: STAGE DESCRIPTION | B2: RBR CODE | C2: EE CODE | D2: Staadium
A3: Site Investigations | B3: SI | C3: UP | D3: Uuringud
A4: Value Engineering | B4: VE | C4: VE | D4: Väärtuspõhine alternatiivide võrdlus
A5: Preliminary design | B5: PD | C5: EP | D5: Eelprojekt
A6: Master Design | B6: MD | C6: PP | D6: Põhiprojekt
A7: Detailed Technical Design | B7: DTD | C7: TP | D7: Tööprojekt
A8: Construction | B8: CO | C8: TJ | D8: Teostusprojekt
A9: Operation | B9: OP | C9: OP | D9: Opereerimine
A10: Demolition | B10: DE | C10: LP | D10: Lammutusprojekt
A12: Techinis darbu projektas - LST 1516:2015 | B12: TDP
A13: Būvprojekts minimālā sastāvā - LBN 202-15 | B13: MBP
B14: To be continued if required. Any code and description shall be agreed with the Client.

Sheet ACTIVITY & DISCIPLINE CODE
B1: Folder number | C1: Activity/Discipline code description | D1: Volsys. Code | E1: Folder number | F1: Activity/Discipline description RBR | G1: Activity/Discipline code | J1: Activity/Discipline description EHR | K1: Activity/Discipline description MNT | L1: Rev date | M1: Rev by
G2: RBR | H2: EHR | I2: MNT
A3: Overall (0-OV) | B3: 000 | C3: Model | E3: 01 | F3: landXML | G3: MO | H3: AA | I3: -
E4: 02 | F4: IFC | G4: MO | H4: AA | I4: -
E5: 03 | F5: RVT | G5: MO | H5: AA | I5: -
E6: 04 | F6: NWD | G6: MO | H6: AA | I6: -
E7: ... | F7: ... | G7: MO | H7: AA | I7: -
B8: 001 | C8: Minutes of Meeting | F8: Minutes of Meeting | G8: MOM | H8: AA | I8: -
B9: 002 | C9: General design documentation | D9: VOLSYS. CODE | E9: 01 | F9: General | G9: GE | H9: AA | I9: - | J9: Üldosa | K9: Üldosa
E10: 02 | F10: Conditions for Design | G10: GE | H10: AA | I10: PT | J10: Üldosa | K10: projekteerimistingimused
E11: 03 | F11: Terms of Reference | G11: GE | H11: AA | I11: LY | J11: Üldosa | K11: lähteülesanne
E12: 04 | F12: Technical Conditions | G12: GE | H12: AA | I12: TT | J12: Üldosa | K12: tehnilised tingimused
E13: 05 | F13: Initial Data | G13: GE | H13: AA | I13: AD | J13: Üldosa | K13: lähteandmed
E14: 06 | F14: Approvals | G14: GE | H14: AA | I14: KK | J14: Üldosa | K14: kooskõlastused
E15: 07 | F15: Road Safety Audit | G15: GE | H15: AA | I15: LA | J15: Üldosa | K15: liiklusohutuse audit
E16: 08 | F16: Appraisal | G16: GE | H16: AA | I16: EK | J16: Üldosa | K16: ekspertiis
E17: 09 | F17: Agreement with landowners | G17: GE | H17: AA | I17: MO | J17: Üldosa | K17: kokkulepped maaomanikega
E18: 10 | F18: Building Permit | G18: GE | H18: AA | I18: BP | J18: Üldosa | K18: ehitusluba
E19: 11 | F19: Road pavement calculation | G19: GE | H19: AA | I19: KA | J19: Üldosa | K19: kattendiarvutus
E20: 12 | F20: Cost List | G20: GE | H20: AA | I20: CL | J20: Üldosa | K20: kululoend
E21: 13 | F21: Application for Funding | G21: GE | H21: AA | I21: RK | J21: Üldosa | K21: rahastustaotlus
E22: 14 | F22: Land allocation Plan | G22: GE | H22: AA | I22: KY | J22: Üldosa | K22: ümberkruntimiskava (krundijaotuskava)
E23: 15 | F23: General technical solutions | G23: GE | H23: AA | I23: KY | J23: Üldosa
B24: 003 | C24: Investigations, Surveys and Studies | E24: 01 | F24: Geological Investigations | G24: IS | H24: AA | I24: GL | J24: Üldosa | K24: geoloogiline uuring
E25: 02 | F25: Traffic Survey | G25: IS | H25: AA | I25: LU | J25: Üldosa | K25: liiklusuuring
E26: 03 | F26: Flora/Fauna Survey | G26: IS | H26: AA | I26: FU | J26: Üldosa | K26: taimsetiku/loomastiku uuring
E27: 04 | F27: Archeological Survey | G27: IS | H27: AA | I27: AU | J27: Üldosa | K27: arheoloogiline uuring
E28: 05 | F28: Topographic Survey | G28: IS | H28: AA | I28: GD | J28: Üldosa | K28: topogeodeesia
E29: 06 | F29: Noise Survey | G29: IS | H29: AA | I29: MU | J29: Üldosa | K29: müra uuring
E30: 07 | F30: Enviormental screening | G30: IS | H30: AA | I30: KE | J30: Üldosa | K30: keskkonnamõju eelhinnang
E31: 08 | F31: EIA | G31: IS | H31: AA | I31: KH | J31: Üldosa | K31: keskkonnamõju hinnang (KMH või KSH)
E32: 09 | F32: Feasibilty study | G32: IS | H32: AA | I32: TU | J32: Üldosa | K32: teostatavusuuring
E33: 10 | F33: Other | G33: IS | H33: AA | I33: ZZ | J33: Üldosa | K33: muu
B34: 004 | C34: Demolition | E34: 01 | F34: Architecture, Building structures & Service (Demolition) | G34: DE | H34: AA | I34: - | J34: Üldosa
E35: 02 | F35: Civil & Structures (Demolition) | G35: DE | H35: AA | I35: - | J35: Üldosa
E36: 03 | F36: Electrical (Demolition) | G36: DE | H36: AA | I36: - | J36: Üldosa
E37: 04 | F37: Fleet (Demolition) | G37: DE | H37: AA | I37: - | J37: Üldosa
E38: 05 | F38: Property (Demolition) | G38: DE | H38: AA | I38: - | J38: Üldosa
E39: 06 | F39: Signalling & Control Systems (Demolition) | G39: DE | H39: AA | I39: - | J39: Üldosa
E40: 07 | F40: Information Technology & Telecommunications System (Demolition) | G40: DE | H40: AA | I40: - | J40: Üldosa
...
